Workbook

Sheet Scoring
J1: Full Test | L1: Corrected Test
A2: Recorded Key ID | B2: Edited Key ID | C2: Recorded Student ID | D2: Edited StudentID | E2: As formula | G2: As Value + Edited | J2: M/C Correct | K2: T/F Correct | L2: M/C Correct | M2: T/F Correct | N2: Raw Score | O2: Adjusted Score | P2: Z value
E3: Student Name | F3: Section | G3: Student Name | H3: Section | Q3: Q1 | R3: Q2 | S3: Q3 | T3: Q4 | U3: Q5 | V3: Q6 | W3: Q7 | X3: Q8 | Y3: Q9 | Z3: Q10 | AA3: Q11 | AB3: Q12 | AC3: Q13 | AD3: Q14 | AE3: Q15 | AF3: Q16 | AG3: Q17 | AH3: Q18 | AI3: Q19 | AJ3: Q20 | AK3: Q21 | AL3: Q22 | AM3: Q23 | AN3: Q24 | AO3: Q25 | AP3: Q26 | AQ3: Q27 | AR3: Q28 | AS3: Q29 | AT3: Q30 | AU3: Q31 | AV3: Q32 | AW3: Q33 | AX3: Q34 | AY3: Q35
P5: Ver A key | Q5: B | R5: A | S5: A | T5: C | U5: C | V5: D | W5: C | X5: C | Y5: C | Z5: D | AA5: C | AB5: C | AC5: C | AD5: C | AE5: D | AF5: C | AG5: A | AH5: B | AI5: B | AJ5: D | AK5: C | AL5: D | AM5: C | AN5: D | AO5: B | AP5: A | AQ5: A | AR5: A | AS5: B | AT5: B | AU5: A | AV5: B | AW5: B | AX5: A | AY5: B
P6: Ver B key | Q6: A | R6: A | S6: C | T6: D | U6: C | V6: C | W6: C | X6: D | Y6: C | Z6: C | AA6: C | AB6: C | AC6: D | AD6: C | AE6: C | AF6: A | AG6: B | AH6: B | AI6: B | AJ6: C | AK6: D | AL6: D | AM6: C | AN6: D | AO6: B | AP6: A | AQ6: B | AR6: B | AS6: A | AT6: A | AU6: A | AV6: B | AW6: A | AX6: A | AY6: B
A7: Count = | B7: =COUNT(D8:D59) -> 52
A8: A | B8: =A8 -> A | C8: 1043694 | D8: 1043694 | E8: =_xlfn.XLOOKUP(D8,'Student Roster'!A:A,'Student Roster'!B:B, "Not Found") -> Khan, Hamza | F8: =_xlfn.XLOOKUP(D8,'Student Roster'!A:A,'Student Roster'!C:C, "Not Found") -> 43958 | G8: Khan, Hamza | H8: 43958 | J8: {=SUMPRODUCT(--(Q8:AO8=IF(B8="A",$Q$5:$AO$5,$Q$6:$AO$6)))} -> 22 | K8: {=SUMPRODUCT(--(AP8:AY8=IF(B8="A",$AP$5:$AY$5,$AP$6:$AY$6)))} -> 8 | L8: {=SUMPRODUCT(--($Q8:$AO8 = IF($B8="A", $Q$5:$AO$5, $Q$6:$AO$6)),--IF($B8="A", (COLUMN($Q8:$AO8)<>COLUMN($W$8)), (COLUMN($Q8:$AO8)<>COLUMN($Z$8))))} -> 21 | M8: =K8 -> 8 | N8: =L8*3+M8 -> 71 | O8: =N8*100/(24*3+10) -> 86.585366 | P8: =(O8-$O$62)/$O$63 -> 1.5617191 | Q8: B | R8: A | S8: A | T8: C | U8: C | V8: C | W8: C | X8: C | Y8: C | Z8: D | AA8: C | AB8: C | AC8: C | AD8: C | AE8: B | AF8: C | AG8: A | AH8: B | AI8: B | AJ8: D | AK8: D | AL8: D | AM8: C | AN8: D | AO8: B | AP8: A | AQ8: A | AR8: A | AS8: B | AT8: B | AU8: A | AV8: B | AW8: A | AX8: A | AY8: A
A9: A | B9: =A9 -> A | C9: 910945 | D9: 910945 | E9: =_xlfn.XLOOKUP(D9,'Student Roster'!A:A,'Student Roster'!B:B, "Not Found") -> Garza, Liliana | F9: =_xlfn.XLOOKUP(D9,'Student Roster'!A:A,'Student Roster'!C:C, "Not Found") -> 43958 | G9: Garza, Liliana | H9: 43958 | J9: {=SUMPRODUCT(--(Q9:AO9=IF(B9="A",$Q$5:$AO$5,$Q$6:$AO$6)))} -> 11 | K9: {=SUMPRODUCT(--(AP9:AY9=IF(B9="A",$AP$5:$AY$5,$AP$6:$AY$6)))} -> 7 | L9: {=SUMPRODUCT(--($Q9:$AO9 = IF($B9="A", $Q$5:$AO$5, $Q$6:$AO$6)),--IF($B9="A", (COLUMN($Q9:$AO9)<>COLUMN($W$8)), (COLUMN($Q9:$AO9)<>COLUMN($Z$8))))} -> 10 | M9: =K9 -> 7 | N9: =L9*3+M9 -> 37 | O9: =N9*100/(24*3+10) -> 45.121951 | P9: =(O9-$O$62)/$O$63 -> -0.76441347 | Q9: D | R9: A | S9: B | T9: C | U9: D | V9: D | W9: C | X9: B | Y9: B | Z9: C | AA9: C | AB9: D | AC9: D | AD9: D | AE9: D | AF9: C | AG9: C | AH9: B | AI9: A | AJ9: B | AK9: C | AL9: D | AM9: A | AN9: D | AO9: C | AP9: B | AQ9: A | AR9: A | AS9: B | AT9: B | AU9: A | AV9: B | AW9: A | AX9: A | AY9: A
A10: A | B10: =A10 -> A | C10: 792916 | D10: 792916 | E10: =_xlfn.XLOOKUP(D10,'Student Roster'!A:A,'Student Roster'!B:B, "Not Found") -> Parada, Jennifer | F10: =_xlfn.XLOOKUP(D10,'Student Roster'!A:A,'Student Roster'!C:C, "Not Found") -> 43958 | G10: Parada, Jennifer | H10: 43958 | J10: {=SUMPRODUCT(--(Q10:AO10=IF(B10="A",$Q$5:$AO$5,$Q$6:$AO$6)))} -> 15 | K10: {=SUMPRODUCT(--(AP10:AY10=IF(B10="A",$AP$5:$AY$5,$AP$6:$AY$6)))} -> 7 | L10: {=SUMPRODUCT(--($Q10:$AO10 = IF($B10="A", $Q$5:$AO$5, $Q$6:$AO$6)),--IF($B10="A", (COLUMN($Q10:$AO10)<>COLUMN($W$8)), (COLUMN($Q10:$AO10)<>COLUMN($Z$8))))} -> 14 | M10: =K10 -> 7 | N10: =L10*3+M10 -> 49 | O10: =N10*100/(24*3+10) -> 59.756098 | P10: =(O10-$O$62)/$O$63 -> 0.056574491 | Q10: A | R10: C | S10: B | T10: E | U10: D | V10: D | W10: C | X10: C | Y10: C | Z10: D | AA10: C | AB10: D | AC10: C | AD10: B | AE10: D | AF10: C | AG10: A | AH10: B | AI10: A | AJ10: D | AK10: C | AL10: D | AM10: B | AN10: D | AO10: C | AP10: B | AQ10: A | AR10: A | AS10: B | AT10: A | AU10: A | AV10: B | AW10: A | AX10: A | AY10: B
A11: BLANK | B11: A | C11: 759215 | D11: 759215 | E11: =_xlfn.XLOOKUP(D11,'Student Roster'!A:A,'Student Roster'!B:B, "Not Found") -> Castro, Socorro | F11: =_xlfn.XLOOKUP(D11,'Student Roster'!A:A,'Student Roster'!C:C, "Not Found") -> 43958 | G11: Castro, Socorro | H11: 43958 | J11: {=SUMPRODUCT(--(Q11:AO11=IF(B11="A",$Q$5:$AO$5,$Q$6:$AO$6)))} -> 12 | K11: {=SUMPRODUCT(--(AP11:AY11=IF(B11="A",$AP$5:$AY$5,$AP$6:$AY$6)))} -> 8 | L11: {=SUMPRODUCT(--($Q11:$AO11 = IF($B11="A", $Q$5:$AO$5, $Q$6:$AO$6)),--IF($B11="A", (COLUMN($Q11:$AO11)<>COLUMN($W$8)), (COLUMN($Q11:$AO11)<>COLUMN($Z$8))))} -> 11 | M11: =K11 -> 8 | N11: =L11*3+M11 -> 41 | O11: =N11*100/(24*3+10) -> 50 | P11: =(O11-$O$62)/$O$63 -> -0.49075082 | Q11: C | R11: C | S11: C | T11: C | U11: C | V11: D | W11: C | X11: D | Y11: C | Z11: D | AA11: C | AB11: B | AC11: C | AD11: D | AE11: A | AF11: C | AG11: D | AH11: B | AI11: C | AJ11: C | AK11: C | AL11: C | AM11: C | AN11: E | AO11: D | AP11: A | AQ11: A | AR11: B | AS11: A | AT11: B | AU11: A | AV11: B | AW11: B | AX11: A | AY11: B
A12: A | B12: =A12 -> A | C12: 754151 | D12: 754151 | E12: =_xlfn.XLOOKUP(D12,'Student Roster'!A:A,'Student Roster'!B:B, "Not Found") -> Zavala, Nia | F12: =_xlfn.XLOOKUP(D12,'Student Roster'!A:A,'Student Roster'!C:C, "Not Found") -> 43958 | G12: Zavala, Nia | H12: 43958 | J12: {=SUMPRODUCT(--(Q12:AO12=IF(B12="A",$Q$5:$AO$5,$Q$6:$AO$6)))} -> 17 | K12: {=SUMPRODUCT(--(AP12:AY12=IF(B12="A",$AP$5:$AY$5,$AP$6:$AY$6)))} -> 2 | L12: {=SUMPRODUCT(--($Q12:$AO12 = IF($B12="A", $Q$5:$AO$5, $Q$6:$AO$6)),--IF($B12="A", (COLUMN($Q12:$AO12)<>COLUMN($W$8)), (COLUMN($Q12:$AO12)<>COLUMN($Z$8))))} -> 16 | M12: =K12 -> 2 | N12: =L12*3+M12 -> 50 | O12: =N12*100/(24*3+10) -> 60.97561 | P12: =(O12-$O$62)/$O$63 -> 0.12499015 | Q12: B | R12: C | S12: A | T12: C | U12: D | V12: D | W12: C | X12: C | Y12: C | Z12: D | AA12: C | AB12: D | AC12: D | AD12: A | AE12: D | AF12: C | AG12: D | AH12: B | AI12: A | AJ12: D | AK12: C | AL12: D | AM12: C | AN12: D | AO12: A | AP12: B | AQ12: A | AR12: B | AS12: A | AT12: A | AU12: B | AV12: A | AW12: A | AX12: A | AY12: A
A13: A | B13: =A13 -> A | C13: 345856 | D13: 345856 | E13: =_xlfn.XLOOKUP(D13,'Student Roster'!A:A,'Student Roster'!B:B, "Not Found") -> Marquez, Rocelia | F13: =_xlfn.XLOOKUP(D13,'Student Roster'!A:A,'Student Roster'!C:C, "Not Found") -> 43957 | G13: Marquez, Rocelia | H13: 43957 | J13: {=SUMPRODUCT(--(Q13:AO13=IF(B13="A",$Q$5:$AO$5,$Q$6:$AO$6)))} -> 15 | K13: {=SUMPRODUCT(--(AP13:AY13=IF(B13="A",$AP$5:$AY$5,$AP$6:$AY$6)))} -> 5 | L13: {=SUMPRODUCT(--($Q13:$AO13 = IF($B13="A", $Q$5:$AO$5, $Q$6:$AO$6)),--IF($B13="A", (COLUMN($Q13:$AO13)<>COLUMN($W$8)), (COLUMN($Q13:$AO13)<>COLUMN($Z$8))))} -> 14 | M13: =K13 -> 5 | N13: =L13*3+M13 -> 47 | O13: =N13*100/(24*3+10) -> 57.317073 | P13: =(O13-$O$62)/$O$63 -> -0.080256836 | Q13: B | R13: C | S13: C | T13: C | U13: C | V13: A | W13: C | X13: C | Y13: C | Z13: D | AA13: C | AB13: C | AC13: B | AD13: D | AE13: D | AF13: C | AG13: C | AH13: D | AI13: A | AJ13: A | AK13: C | AL13: D | AM13: A | AN13: D | AO13: B | AP13: B | AQ13: A | AR13: A | AS13: A | AT13: B | AU13: A | AV13: B | AW13: A | AX13: B | AY13: A
A14: B | B14: =A14 -> B | D14: 997376 | E14: =_xlfn.XLOOKUP(D14,'Student Roster'!A:A,'Student Roster'!B:B, "Not Found") -> Xiong, Wendy | F14: =_xlfn.XLOOKUP(D14,'Student Roster'!A:A,'Student Roster'!C:C, "Not Found") -> 43958 | G14: Xiong, Wendy | H14: 43958 | J14: {=SUMPRODUCT(--(Q14:AO14=IF(B14="A",$Q$5:$AO$5,$Q$6:$AO$6)))} -> 19 | K14: {=SUMPRODUCT(--(AP14:AY14=IF(B14="A",$AP$5:$AY$5,$AP$6:$AY$6)))} -> 7 | L14: {=SUMPRODUCT(--($Q14:$AO14 = IF($B14="A", $Q$5:$AO$5, $Q$6:$AO$6)),--IF($B14="A", (COLUMN($Q14:$AO14)<>COLUMN($W$8)), (COLUMN($Q14:$AO14)<>COLUMN($Z$8))))} -> 18 | M14: =K14 -> 7 | N14: =L14*3+M14 -> 61 | O14: =N14*100/(24*3+10) -> 74.390244 | P14: =(O14-$O$62)/$O$63 -> 0.87756245 | Q14: A | R14: A | S14: C | T14: D | U14: E | V14: C | W14: B | X14: D | Y14: C | Z14: C | AA14: B | AB14: C | AC14: D | AD14: A | AE14: B | AF14: D | AG14: B | AH14: B | AI14: B | AJ14: C | AK14: D | AL14: D | AM14: C | AN14: D | AO14: B | AP14: A | AQ14: B | AR14: A | AS14: A | AT14: A | AU14: B | AV14: A | AW14: A | AX14: A | AY14: B
A15: B | B15: =A15 -> B | C15: 808147 | D15: 808147 | E15: =_xlfn.XLOOKUP(D15,'Student Roster'!A:A,'Student Roster'!B:B, "Not Found") -> Martinez, Vanessa | F15: =_xlfn.XLOOKUP(D15,'Student Roster'!A:A,'Student Roster'!C:C, "Not Found") -> 43958 | G15: Martinez, Vanessa | H15: 43958 | J15: {=SUMPRODUCT(--(Q15:AO15=IF(B15="A",$Q$5:$AO$5,$Q$6:$AO$6)))} -> 17 | K15: {=SUMPRODUCT(--(AP15:AY15=IF(B15="A",$AP$5:$AY$5,$AP$6:$AY$6)))} -> 4 | L15: {=SUMPRODUCT(--($Q15:$AO15 = IF($B15="A", $Q$5:$AO$5, $Q$6:$AO$6)),--IF($B15="A", (COLUMN($Q15:$AO15)<>COLUMN($W$8)), (COLUMN($Q15:$AO15)<>COLUMN($Z$8))))} -> 16 | M15: =K15 -> 4 | N15: =L15*3+M15 -> 52 | O15: =N15*100/(24*3+10) -> 63.414634 | P15: =(O15-$O$62)/$O$63 -> 0.26182148 | Q15: A | R15: B | S15: E | T15: D | U15: C | V15: B | W15: D | X15: D | Y15: C | Z15: C | AA15: B | AB15: C | AC15: D | AD15: C | AE15: C | AF15: D | AG15: B | AH15: B | AI15: B | AJ15: C | AK15: C | AL15: D | AM15: C | AN15: D | AO15: C | AP15: A | AQ15: A | AR15: A | AS15: A | AT15: B | AU15: B | AV15: A | AW15: B | AX15: A | AY15: B
A16: B | B16: =A16 -> B | C16: 986455 | D16: 986455 | E16: =_xlfn.XLOOKUP(D16,'Student Roster'!A:A,'Student Roster'!B:B, "Not Found") -> Moua, Haley | F16: =_xlfn.XLOOKUP(D16,'Student Roster'!A:A,'Student Roster'!C:C, "Not Found") -> 43957 | G16: Moua, Haley | H16: 43957 | J16: {=SUMPRODUCT(--(Q16:AO16=IF(B16="A",$Q$5:$AO$5,$Q$6:$AO$6)))} -> 13 | K16: {=SUMPRODUCT(--(AP16:AY16=IF(B16="A",$AP$5:$AY$5,$AP$6:$AY$6)))} -> 6 | L16: {=SUMPRODUCT(--($Q16:$AO16 = IF($B16="A", $Q$5:$AO$5, $Q$6:$AO$6)),--IF($B16="A", (COLUMN($Q16:$AO16)<>COLUMN($W$8)), (COLUMN($Q16:$AO16)<>COLUMN($Z$8))))} -> 13 | M16: =K16 -> 6 | N16: =L16*3+M16 -> 45 | O16: =N16*100/(24*3+10) -> 54.878049 | P16: =(O16-$O$62)/$O$63 -> -0.21708816 | Q16: C | R16: A | S16: A | T16: D | U16: C | V16: A | W16: D | X16: D | Y16: D | Z16: A | AA16: C | AB16: C | AC16: B | AD16: C | AE16: C | AF16: E | AG16: D | AH16: D | AI16: D | AJ16: C | AK16: D | AL16: B | AM16: C | AN16: D | AO16: B | AP16: B | AQ16: B | AR16: A | AS16: A | AT16: A | AU16: A | AV16: A | AW16: B | AX16: A | AY16: B
A17: A | B17: =A17 -> A | C17: 895473 | D17: 895473 | E17: =_xlfn.XLOOKUP(D17,'Student Roster'!A:A,'Student Roster'!B:B, "Not Found") -> Pedroza, Serena | F17: =_xlfn.XLOOKUP(D17,'Student Roster'!A:A,'Student Roster'!C:C, "Not Found") -> 43957 | G17: Pedroza, Serena | H17: 43957 | J17: {=SUMPRODUCT(--(Q17:AO17=IF(B17="A",$Q$5:$AO$5,$Q$6:$AO$6)))} -> 17 | K17: {=SUMPRODUCT(--(AP17:AY17=IF(B17="A",$AP$5:$AY$5,$AP$6:$AY$6)))} -> 8 | L17: {=SUMPRODUCT(--($Q17:$AO17 = IF($B17="A", $Q$5:$AO$5, $Q$6:$AO$6)),--IF($B17="A", (COLUMN($Q17:$AO17)<>COLUMN($W$8)), (COLUMN($Q17:$AO17)<>COLUMN($Z$8))))} -> 16 | M17: =K17 -> 8 | N17: =L17*3+M17 -> 56 | O17: =N17*100/(24*3+10) -> 68.292683 | P17: =(O17-$O$62)/$O$63 -> 0.53548414 | Q17: B | R17: A | S17: A | T17: C | U17: C | V17: D | W17: C | X17: C | Y17: B | Z17: D | AA17: E | AB17: A | AC17: D | AD17: A | AE17: B | AF17: C | AG17: E | AH17: B | AI17: B | AJ17: D | AK17: C | AL17: D | AM17: B | AN17: D | AO17: B | AP17: A | AQ17: A | AR17: A | AS17: B | AT17: B | AU17: A | AV17: B | AW17: A | AX17: A | AY17: A
A18: B | B18: =A18 -> B | C18: 778750 | D18: 778750 | E18: =_xlfn.XLOOKUP(D18,'Student Roster'!A:A,'Student Roster'!B:B, "Not Found") -> Garcia, Jovanna | F18: =_xlfn.XLOOKUP(D18,'Student Roster'!A:A,'Student Roster'!C:C, "Not Found") -> 43958 | G18: Garcia, Jovanna | H18: 43958 | J18: {=SUMPRODUCT(--(Q18:AO18=IF(B18="A",$Q$5:$AO$5,$Q$6:$AO$6)))} -> 16 | K18: {=SUMPRODUCT(--(AP18:AY18=IF(B18="A",$AP$5:$AY$5,$AP$6:$AY$6)))} -> 7 | L18: {=SUMPRODUCT(--($Q18:$AO18 = IF($B18="A", $Q$5:$AO$5, $Q$6:$AO$6)),--IF($B18="A", (COLUMN($Q18:$AO18)<>COLUMN($W$8)), (COLUMN($Q18:$AO18)<>COLUMN($Z$8))))} -> 15 | M18: =K18 -> 7 | N18: =L18*3+M18 -> 52 | O18: =N18*100/(24*3+10) -> 63.414634 | P18: =(O18-$O$62)/$O$63 -> 0.26182148 | Q18: A | R18: A | S18: C | T18: D | U18: E | V18: D | W18: C | X18: D | Y18: A | Z18: C | AA18: C | AB18: C | AC18: A | AD18: C | AE18: C | AF18: A | AG18: A | AH18: C | AI18: A | AJ18: C | AK18: D | AL18: C | AM18: C | AN18: D | AO18: C | AP18: A | AQ18: B | AR18: B | AS18: A | AT18: A | AU18: A | AV18: A | AW18: B | AX18: A | AY18: A
A19: A | B19: =A19 -> A | D19: 997908 | E19: =_xlfn.XLOOKUP(D19,'Student Roster'!A:A,'Student Roster'!B:B, "Not Found") -> Landeros, Hidai | F19: =_xlfn.XLOOKUP(D19,'Student Roster'!A:A,'Student Roster'!C:C, "Not Found") -> 43958 | G19: Landeros, Hidai | H19: 43958 | J19: {=SUMPRODUCT(--(Q19:AO19=IF(B19="A",$Q$5:$AO$5,$Q$6:$AO$6)))} -> 9 | K19: {=SUMPRODUCT(--(AP19:AY19=IF(B19="A",$AP$5:$AY$5,$AP$6:$AY$6)))} -> 4 | L19: {=SUMPRODUCT(--($Q19:$AO19 = IF($B19="A", $Q$5:$AO$5, $Q$6:$AO$6)),--IF($B19="A", (COLUMN($Q19:$AO19)<>COLUMN($W$8)), (COLUMN($Q19:$AO19)<>COLUMN($Z$8))))} -> 8 | M19: =K19 -> 4 | N19: =L19*3+M19 -> 28 | O19: =N19*100/(24*3+10) -> 34.146341 | P19: =(O19-$O$62)/$O$63 -> -1.3801544 | Q19: D | R19: C | S19: D | T19: E | U19: B | V19: D | W19: C | X19: B | Y19: C | Z19: E | AA19: E | AB19: B | AC19: C | AD19: C | AE19: B | AF19: C | AG19: E | AH19: D | AI19: B | AJ19: A | AK19: D | AL19: C | AM19: A | AN19: D | AO19: B | AP19: A | AQ19: A | AR19: B | AS19: A | AT19: A | AU19: A | AV19: B | AW19: A | AX19: B | AY19: A
A20: B | B20: =A20 -> B | C20: 547169 | D20: 547169 | E20: =_xlfn.XLOOKUP(D20,'Student Roster'!A:A,'Student Roster'!B:B, "Not Found") -> San Roman, Jesus | F20: =_xlfn.XLOOKUP(D20,'Student Roster'!A:A,'Student Roster'!C:C, "Not Found") -> 43958 | G20: San Roman, Jesus | H20: 43958 | J20: {=SUMPRODUCT(--(Q20:AO20=IF(B20="A",$Q$5:$AO$5,$Q$6:$AO$6)))} -> 17 | K20: {=SUMPRODUCT(--(AP20:AY20=IF(B20="A",$AP$5:$AY$5,$AP$6:$AY$6)))} -> 8 | L20: {=SUMPRODUCT(--($Q20:$AO20 = IF($B20="A", $Q$5:$AO$5, $Q$6:$AO$6)),--IF($B20="A", (COLUMN($Q20:$AO20)<>COLUMN($W$8)), (COLUMN($Q20:$AO20)<>COLUMN($Z$8))))} -> 16 | M20: =K20 -> 8 | N20: =L20*3+M20 -> 56 | O20: =N20*100/(24*3+10) -> 68.292683 | P20: =(O20-$O$62)/$O$63 -> 0.53548414 | Q20: C | R20: A | S20: C | T20: D | U20: C | V20: C | W20: C | X20: D | Y20: A | Z20: C | AA20: C | AB20: C | AC20: B | AD20: A | AE20: C | AF20: D | AG20: B | AH20: B | AI20: C | AJ20: D | AK20: D | AL20: D | AM20: A | AN20: D | AO20: B | AP20: A | AQ20: B | AR20: B | AS20: A | AT20: A | AU20: A | AV20: A | AW20: B | AX20: A | AY20: B
A21: B | B21: =A21 -> B | C21: 934815 | D21: 934915 | E21: =_xlfn.XLOOKUP(D21,'Student Roster'!A:A,'Student Roster'!B:B, "Not Found") -> Rodriguez, Ericke | F21: =_xlfn.XLOOKUP(D21,'Student Roster'!A:A,'Student Roster'!C:C, "Not Found") -> 43958 | G21: Rodriguez, Ericke | H21: 43958 | J21: {=SUMPRODUCT(--(Q21:AO21=IF(B21="A",$Q$5:$AO$5,$Q$6:$AO$6)))} -> 18 | K21: {=SUMPRODUCT(--(AP21:AY21=IF(B21="A",$AP$5:$AY$5,$AP$6:$AY$6)))} -> 6 | L21: {=SUMPRODUCT(--($Q21:$AO21 = IF($B21="A", $Q$5:$AO$5, $Q$6:$AO$6)),--IF($B21="A", (COLUMN($Q21:$AO21)<>COLUMN($W$8)), (COLUMN($Q21:$AO21)<>COLUMN($Z$8))))} -> 17 | M21: =K21 -> 6 | N21: =L21*3+M21 -> 57 | O21: =N21*100/(24*3+10) -> 69.512195 | P21: =(O21-$O$62)/$O$63 -> 0.6038998 | Q21: A | R21: A | S21: C | T21: D | U21: C | V21: B | W21: C | X21: D | Y21: C | Z21: C | AA21: C | AB21: C | AC21: D | AD21: B | AE21: C | AF21: E | AG21: B | AH21: B | AI21: A | AJ21: B | AK21: D | AL21: A | AM21: D | AN21: D | AO21: B | AP21: A | AQ21: B | AR21: A | AS21: B | AT21: A | AU21: A | AV21: A | AW21: B | AX21: A | AY21: B
A22: BLANK | B22: A | C22: 1063699 | D22: 1063699 | E22: =_xlfn.XLOOKUP(D22,'Student Roster'!A:A,'Student Roster'!B:B, "Not Found") -> Garcia-Hernandez, Allison | F22: =_xlfn.XLOOKUP(D22,'Student Roster'!A:A,'Student Roster'!C:C, "Not Found") -> 43958 | G22: Garcia-Hernandez, Allison | H22: 43958 | J22: {=SUMPRODUCT(--(Q22:AO22=IF(B22="A",$Q$5:$AO$5,$Q$6:$AO$6)))} -> 12 | K22: {=SUMPRODUCT(--(AP22:AY22=IF(B22="A",$AP$5:$AY$5,$AP$6:$AY$6)))} -> 8 | L22: {=SUMPRODUCT(--($Q22:$AO22 = IF($B22="A", $Q$5:$AO$5, $Q$6:$AO$6)),--IF($B22="A", (COLUMN($Q22:$AO22)<>COLUMN($W$8)), (COLUMN($Q22:$AO22)<>COLUMN($Z$8))))} -> 12 | M22: =K22 -> 8 | N22: =L22*3+M22 -> 44 | O22: =N22*100/(24*3+10) -> 53.658537 | P22: =(O22-$O$62)/$O$63 -> -0.28550383 | Q22: D | R22: A | S22: A | T22: C | U22: BLANK | V22: B | W22: A | X22: B | Y22: C | Z22: D | AA22: E | AB22: C | AC22: D | AD22: C | AE22: D | AF22: B | AG22: D | AH22: B | AI22: B | AJ22: B | AK22: C | AL22: BLANK | AM22: B | AN22: D | AO22: C | AP22: A | AQ22: A | AR22: A | AS22: B | AT22: B | AU22: A | AV22: B | AW22: A | AX22: A | AY22: A
A23: BLANK | B23: B | C23: 994114 | D23: 994114 | E23: =_xlfn.XLOOKUP(D23,'Student Roster'!A:A,'Student Roster'!B:B, "Not Found") -> Corea, Kristie | F23: =_xlfn.XLOOKUP(D23,'Student Roster'!A:A,'Student Roster'!C:C, "Not Found") -> 43957 | G23: Corea, Kristie | H23: 43957 | J23: {=SUMPRODUCT(--(Q23:AO23=IF(B23="A",$Q$5:$AO$5,$Q$6:$AO$6)))} -> 12 | K23: {=SUMPRODUCT(--(AP23:AY23=IF(B23="A",$AP$5:$AY$5,$AP$6:$AY$6)))} -> 5 | L23: {=SUMPRODUCT(--($Q23:$AO23 = IF($B23="A", $Q$5:$AO$5, $Q$6:$AO$6)),--IF($B23="A", (COLUMN($Q23:$AO23)<>COLUMN($W$8)), (COLUMN($Q23:$AO23)<>COLUMN($Z$8))))} -> 11 | M23: =K23 -> 5 | N23: =L23*3+M23 -> 38 | O23: =N23*100/(24*3+10) -> 46.341463 | P23: =(O23-$O$62)/$O$63 -> -0.69599781 | Q23: C | R23: A | S23: E | T23: A | U23: C | V23: A | W23: C | X23: D | Y23: C | Z23: C | AA23: C | AB23: B | AC23: D | AD23: C | AE23: B | AF23: E | AG23: D | AH23: A | AI23: B | AJ23: B | AK23: D | AL23: D | AM23: B | AN23: C | AO23: D | AP23: A | AQ23: B | AR23: A | AS23: B | AT23: A | AU23: A | AV23: A | AW23: B | AX23: A | AY23: A
A24: B | B24: =A24 -> B | C24: 737921 | D24: 737921 | E24: =_xlfn.XLOOKUP(D24,'Student Roster'!A:A,'Student Roster'!B:B, "Not Found") -> Fang, Pa | F24: =_xlfn.XLOOKUP(D24,'Student Roster'!A:A,'Student Roster'!C:C, "Not Found") -> 43957 | G24: Fang, Pa | H24: 43957 | J24: {=SUMPRODUCT(--(Q24:AO24=IF(B24="A",$Q$5:$AO$5,$Q$6:$AO$6)))} -> 8 | K24: {=SUMPRODUCT(--(AP24:AY24=IF(B24="A",$AP$5:$AY$5,$AP$6:$AY$6)))} -> 5 | L24: {=SUMPRODUCT(--($Q24:$AO24 = IF($B24="A", $Q$5:$AO$5, $Q$6:$AO$6)),--IF($B24="A", (COLUMN($Q24:$AO24)<>COLUMN($W$8)), (COLUMN($Q24:$AO24)<>COLUMN($Z$8))))} -> 8 | M24: =K24 -> 5 | N24: =L24*3+M24 -> 29 | O24: =N24*100/(24*3+10) -> 35.365854 | P24: =(O24-$O$62)/$O$63 -> -1.3117388 | Q24: C | R24: D | S24: C | T24: D | U24: C | V24: A | W24: B | X24: B | Y24: D | Z24: A | AA24: B | AB24: B | AC24: C | AD24: A | AE24: C | AF24: D | AG24: B | AH24: C | AI24: C | AJ24: B | AK24: D | AL24: B | AM24: C | AN24: D | AO24: C | AP24: A | AQ24: B | AR24: B | AS24: A | AT24: A | AU24: B | AV24: A | AW24: B | AX24: B | AY24: A
A25: A | B25: =A25 -> A | C25: 871988 | D25: 871988 | E25: =_xlfn.XLOOKUP(D25,'Student Roster'!A:A,'Student Roster'!B:B, "Not Found") -> Hernan, Jazmine | F25: =_xlfn.XLOOKUP(D25,'Student Roster'!A:A,'Student Roster'!C:C, "Not Found") -> 43957 | G25: Hernan, Jazmine | H25: 43957 | J25: {=SUMPRODUCT(--(Q25:AO25=IF(B25="A",$Q$5:$AO$5,$Q$6:$AO$6)))} -> 13 | K25: {=SUMPRODUCT(--(AP25:AY25=IF(B25="A",$AP$5:$AY$5,$AP$6:$AY$6)))} -> 7 | L25: {=SUMPRODUCT(--($Q25:$AO25 = IF($B25="A", $Q$5:$AO$5, $Q$6:$AO$6)),--IF($B25="A", (COLUMN($Q25:$AO25)<>COLUMN($W$8)), (COLUMN($Q25:$AO25)<>COLUMN($Z$8))))} -> 12 | M25: =K25 -> 7 | N25: =L25*3+M25 -> 43 | O25: =N25*100/(24*3+10) -> 52.439024 | P25: =(O25-$O$62)/$O$63 -> -0.35391949 | Q25: C | R25: C | S25: B | T25: C | U25: C | V25: A | W25: C | X25: B | Y25: B | Z25: D | AA25: C | AB25: C | AC25: C | AD25: D | AE25: A | AF25: B | AG25: D | AH25: B | AI25: A | AJ25: D | AK25: C | AL25: D | AM25: C | AN25: D | AO25: D | AP25: B | AQ25: A | AR25: A | AS25: B | AT25: A | AU25: A | AV25: B | AW25: B | AX25: A | AY25: A
A26: A | B26: =A26 -> A | C26: 576373 | D26: 576373 | E26: =_xlfn.XLOOKUP(D26,'Student Roster'!A:A,'Student Roster'!B:B, "Not Found") -> Ceballos, Ariel | F26: =_xlfn.XLOOKUP(D26,'Student Roster'!A:A,'Student Roster'!C:C, "Not Found") -> 43957 | G26: Ceballos, Ariel | H26: 43957 | J26: {=SUMPRODUCT(--(Q26:AO26=IF(B26="A",$Q$5:$AO$5,$Q$6:$AO$6)))} -> 18 | K26: {=SUMPRODUCT(--(AP26:AY26=IF(B26="A",$AP$5:$AY$5,$AP$6:$AY$6)))} -> 8 | L26: {=SUMPRODUCT(--($Q26:$AO26 = IF($B26="A", $Q$5:$AO$5, $Q$6:$AO$6)),--IF($B26="A", (COLUMN($Q26:$AO26)<>COLUMN($W$8)), (COLUMN($Q26:$AO26)<>COLUMN($Z$8))))} -> 18 | M26: =K26 -> 8 | N26: =L26*3+M26 -> 62 | O26: =N26*100/(24*3+10) -> 75.609756 | P26: =(O26-$O$62)/$O$63 -> 0.94597812 | Q26: B | R26: A | S26: B | T26: C | U26: C | V26: D | W26: A | X26: A | Y26: C | Z26: D | AA26: C | AB26: C | AC26: B | AD26: C | AE26: D | AF26: C | AG26: D | AH26: B | AI26: B | AJ26: D | AK26: B | AL26: D | AM26: A | AN26: D | AO26: B | AP26: A | AQ26: A | AR26: A | AS26: B | AT26: B | AU26: B | AV26: B | AW26: A | AX26: A | AY26: B
A27: A | B27: =A27 -> A | C27: 1065569 | D27: 1065569 | E27: =_xlfn.XLOOKUP(D27,'Student Roster'!A:A,'Student Roster'!B:B, "Not Found") -> Bryant, Tajanique | F27: =_xlfn.XLOOKUP(D27,'Student Roster'!A:A,'Student Roster'!C:C, "Not Found") -> 43958 | G27: Bryant, Tajanique | H27: 43958 | J27: {=SUMPRODUCT(--(Q27:AO27=IF(B27="A",$Q$5:$AO$5,$Q$6:$AO$6)))} -> 15 | K27: {=SUMPRODUCT(--(AP27:AY27=IF(B27="A",$AP$5:$AY$5,$AP$6:$AY$6)))} -> 7 | L27: {=SUMPRODUCT(--($Q27:$AO27 = IF($B27="A", $Q$5:$AO$5, $Q$6:$AO$6)),--IF($B27="A", (COLUMN($Q27:$AO27)<>COLUMN($W$8)), (COLUMN($Q27:$AO27)<>COLUMN($Z$8))))} -> 14 | M27: =K27 -> 7 | N27: =L27*3+M27 -> 49 | O27: =N27*100/(24*3+10) -> 59.756098 | P27: =(O27-$O$62)/$O$63 -> 0.056574491 | Q27: A | R27: C | S27: A | T27: C | U27: BLANK | V27: C | W27: C | X27: C | Y27: B | Z27: C | AA27: C | AB27: A | AC27: A | AD27: C | AE27: D | AF27: C | AG27: A | AH27: A | AI27: B | AJ27: B | AK27: C | AL27: D | AM27: C | AN27: D | AO27: B | AP27: A | AQ27: A | AR27: A | AS27: B | AT27: B | AU27: A | AV27: B | AW27: A | AX27: B | AY27: A
A28: A | B28: =A28 -> A | C28: 1068669 | D28: 1068669 | E28: =_xlfn.XLOOKUP(D28,'Student Roster'!A:A,'Student Roster'!B:B, "Not Found") -> Snell, Tricia | F28: =_xlfn.XLOOKUP(D28,'Student Roster'!A:A,'Student Roster'!C:C, "Not Found") -> 43957 | G28: Snell, Tricia | H28: 43957 | J28: {=SUMPRODUCT(--(Q28:AO28=IF(B28="A",$Q$5:$AO$5,$Q$6:$AO$6)))} -> 25 | K28: {=SUMPRODUCT(--(AP28:AY28=IF(B28="A",$AP$5:$AY$5,$AP$6:$AY$6)))} -> 9 | L28: {=SUMPRODUCT(--($Q28:$AO28 = IF($B28="A", $Q$5:$AO$5, $Q$6:$AO$6)),--IF($B28="A", (COLUMN($Q28:$AO28)<>COLUMN($W$8)), (COLUMN($Q28:$AO28)<>COLUMN($Z$8))))} -> 24 | M28: =K28 -> 9 | N28: =L28*3+M28 -> 81 | O28: =N28*100/(24*3+10) -> 98.780488 | P28: =(O28-$O$62)/$O$63 -> 2.2458757 | Q28: B | R28: A | S28: A | T28: C | U28: C | V28: D | W28: C | X28: C | Y28: C | Z28: D | AA28: C | AB28: C | AC28: C | AD28: C | AE28: D | AF28: C | AG28: A | AH28: B | AI28: B | AJ28: D | AK28: C | AL28: D | AM28: C | AN28: D | AO28: B | AP28: A | AQ28: A | AR28: A | AS28: A | AT28: B | AU28: A | AV28: B | AW28: B | AX28: A | AY28: B
A29: B | B29: =A29 -> B | C29: 490011 | D29: 490011 | E29: =_xlfn.XLOOKUP(D29,'Student Roster'!A:A,'Student Roster'!B:B, "Not Found") -> Garcia, Sabrina | F29: =_xlfn.XLOOKUP(D29,'Student Roster'!A:A,'Student Roster'!C:C, "Not Found") -> 43957 | G29: Garcia, Sabrina | H29: 43957 | J29: {=SUMPRODUCT(--(Q29:AO29=IF(B29="A",$Q$5:$AO$5,$Q$6:$AO$6)))} -> 7 | K29: {=SUMPRODUCT(--(AP29:AY29=IF(B29="A",$AP$5:$AY$5,$AP$6:$AY$6)))} -> 5 | L29: {=SUMPRODUCT(--($Q29:$AO29 = IF($B29="A", $Q$5:$AO$5, $Q$6:$AO$6)),--IF($B29="A", (COLUMN($Q29:$AO29)<>COLUMN($W$8)), (COLUMN($Q29:$AO29)<>COLUMN($Z$8))))} -> 7 | M29: =K29 -> 5 | N29: =L29*3+M29 -> 26 | O29: =N29*100/(24*3+10) -> 31.707317 | P29: =(O29-$O$62)/$O$63 -> -1.5169858 | Q29: A | R29: A | S29: E | T29: C | U29: C | V29: C | W29: B | X29: B | Y29: D | Z29: D | AA29: D | AB29: B | AC29: A | AD29: A | AE29: C | AF29: C | AG29: C | AH29: A | AI29: D | AJ29: D | AK29: D | AL29: B | AM29: A | AN29: D | AO29: A | AP29: A | AQ29: B | AR29: A | AS29: B | AT29: A | AU29: A | AV29: A | AW29: B | AX29: A | AY29: A
A30: A | B30: =A30 -> A | C30: 574404 | D30: 574404 | E30: =_xlfn.XLOOKUP(D30,'Student Roster'!A:A,'Student Roster'!B:B, "Not Found") -> Rodriguez, Madison | F30: =_xlfn.XLOOKUP(D30,'Student Roster'!A:A,'Student Roster'!C:C, "Not Found") -> 43958 | G30: Rodriguez, Madison | H30: 43958 | J30: {=SUMPRODUCT(--(Q30:AO30=IF(B30="A",$Q$5:$AO$5,$Q$6:$AO$6)))} -> 18 | K30: {=SUMPRODUCT(--(AP30:AY30=IF(B30="A",$AP$5:$AY$5,$AP$6:$AY$6)))} -> 7 | L30: {=SUMPRODUCT(--($Q30:$AO30 = IF($B30="A", $Q$5:$AO$5, $Q$6:$AO$6)),--IF($B30="A", (COLUMN($Q30:$AO30)<>COLUMN($W$8)), (COLUMN($Q30:$AO30)<>COLUMN($Z$8))))} -> 17 | M30: =K30 -> 7 | N30: =L30*3+M30 -> 58 | O30: =N30*100/(24*3+10) -> 70.731707 | P30: =(O30-$O$62)/$O$63 -> 0.67231546 | Q30: D | R30: A | S30: B | T30: C | U30: A | V30: D | W30: C | X30: C | Y30: C | Z30: D | AA30: C | AB30: C | AC30: D | AD30: A | AE30: D | AF30: C | AG30: D | AH30: B | AI30: B | AJ30: D | AK30: C | AL30: D | AM30: C | AN30: D | AO30: C | AP30: A | AQ30: A | AR30: A | AS30: B | AT30: B | AU30: B | AV30: B | AW30: A | AX30: A | AY30: A
A31: BLANK | B31: B | C31: 1015634 | D31: 1016534 | E31: =_xlfn.XLOOKUP(D31,'Student Roster'!A:A,'Student Roster'!B:B, "Not Found") -> Arellano Cruz, Ashley | F31: =_xlfn.XLOOKUP(D31,'Student Roster'!A:A,'Student Roster'!C:C, "Not Found") -> 43958 | G31: Arellano Cruz, Ashley | H31: 43958 | J31: {=SUMPRODUCT(--(Q31:AO31=IF(B31="A",$Q$5:$AO$5,$Q$6:$AO$6)))} -> 8 | K31: {=SUMPRODUCT(--(AP31:AY31=IF(B31="A",$AP$5:$AY$5,$AP$6:$AY$6)))} -> 5 | L31: {=SUMPRODUCT(--($Q31:$AO31 = IF($B31="A", $Q$5:$AO$5, $Q$6:$AO$6)),--IF($B31="A", (COLUMN($Q31:$AO31)<>COLUMN($W$8)), (COLUMN($Q31:$AO31)<>COLUMN($Z$8))))} -> 8 | M31: =K31 -> 5 | N31: =L31*3+M31 -> 29 | O31: =N31*100/(24*3+10) -> 35.365854 | P31: =(O31-$O$62)/$O$63 -> -1.3117388 | Q31: A | R31: A | S31: E | T31: D | U31: E | V31: B | W31: A | X31: C | Y31: C | Z31: A | AA31: D | AB31: C | AC31: C | AD31: B | AE31: C | AF31: E | AG31: D | AH31: C | AI31: A | AJ31: A | AK31: C | AL31: D | AM31: A | AN31: D | AO31: D | AP31: A | AQ31: B | AR31: B | AS31: B | AT31: A | AU31: A | AV31: A | AW31: B | AX31: B | AY31: A
A32: A | B32: =A32 -> A | D32: 775232 | E32: =_xlfn.XLOOKUP(D32,'Student Roster'!A:A,'Student Roster'!B:B, "Not Found") -> Vargas, Lisa | F32: =_xlfn.XLOOKUP(D32,'Student Roster'!A:A,'Student Roster'!C:C, "Not Found") -> 43957 | G32: Vargas, Lisa | H32: 43957 | J32: {=SUMPRODUCT(--(Q32:AO32=IF(B32="A",$Q$5:$AO$5,$Q$6:$AO$6)))} -> 8 | K32: {=SUMPRODUCT(--(AP32:AY32=IF(B32="A",$AP$5:$AY$5,$AP$6:$AY$6)))} -> 5 | L32: {=SUMPRODUCT(--($Q32:$AO32 = IF($B32="A", $Q$5:$AO$5, $Q$6:$AO$6)),--IF($B32="A", (COLUMN($Q32:$AO32)<>COLUMN($W$8)), (COLUMN($Q32:$AO32)<>COLUMN($Z$8))))} -> 8 | M32: =K32 -> 5 | N32: =L32*3+M32 -> 29 | O32: =N32*100/(24*3+10) -> 35.365854 | P32: =(O32-$O$62)/$O$63 -> -1.3117388 | Q32: B | R32: A | S32: C | T32: E | U32: D | V32: B | W32: B | X32: C | Y32: D | Z32: C | AA32: B | AB32: C | AC32: D | AD32: D | AE32: A | AF32: B | AG32: E | AH32: C | AI32: A | AJ32: D | AK32: C | AL32: B | AM32: C | AN32: D | AO32: A | AP32: A | AQ32: B | AR32: A | AS32: B | AT32: A | AU32: A | AV32: B | AW32: A | AX32: B | AY32: A
A33: A | B33: =A33 -> A | C33: 924739 | D33: 924739 | E33: =_xlfn.XLOOKUP(D33,'Student Roster'!A:A,'Student Roster'!B:B, "Not Found") -> Santos, Madison | F33: =_xlfn.XLOOKUP(D33,'Student Roster'!A:A,'Student Roster'!C:C, "Not Found") -> 43957 | G33: Santos, Madison | H33: 43957 | J33: {=SUMPRODUCT(--(Q33:AO33=IF(B33="A",$Q$5:$AO$5,$Q$6:$AO$6)))} -> 14 | K33: {=SUMPRODUCT(--(AP33:AY33=IF(B33="A",$AP$5:$AY$5,$AP$6:$AY$6)))} -> 6 | L33: {=SUMPRODUCT(--($Q33:$AO33 = IF($B33="A", $Q$5:$AO$5, $Q$6:$AO$6)),--IF($B33="A", (COLUMN($Q33:$AO33)<>COLUMN($W$8)), (COLUMN($Q33:$AO33)<>COLUMN($Z$8))))} -> 13 | M33: =K33 -> 6 | N33: =L33*3+M33 -> 45 | O33: =N33*100/(24*3+10) -> 54.878049 | P33: =(O33-$O$62)/$O$63 -> -0.21708816 | Q33: C | R33: C | S33: C | T33: C | U33: A | V33: D | W33: C | X33: C | Y33: C | Z33: D | AA33: E | AB33: C | AC33: C | AD33: A | AE33: B | AF33: D | AG33: D | AH33: B | AI33: C | AJ33: D | AK33: C | AL33: D | AM33: D | AN33: D | AO33: B | AP33: B | AQ33: A | AR33: A | AS33: B | AT33: B | AU33: A | AV33: B | AW33: A | AX33: B | AY33: A
A34: BLANK | B34: B | C34: 1035199 | D34: 1035199 | E34: =_xlfn.XLOOKUP(D34,'Student Roster'!A:A,'Student Roster'!B:B, "Not Found") -> Pascale, Teah | F34: =_xlfn.XLOOKUP(D34,'Student Roster'!A:A,'Student Roster'!C:C, "Not Found") -> 43957 | G34: Pascale, Teah | H34: 43957 | J34: {=SUMPRODUCT(--(Q34:AO34=IF(B34="A",$Q$5:$AO$5,$Q$6:$AO$6)))} -> 13 | K34: {=SUMPRODUCT(--(AP34:AY34=IF(B34="A",$AP$5:$AY$5,$AP$6:$AY$6)))} -> 8 | L34: {=SUMPRODUCT(--($Q34:$AO34 = IF($B34="A", $Q$5:$AO$5, $Q$6:$AO$6)),--IF($B34="A", (COLUMN($Q34:$AO34)<>COLUMN($W$8)), (COLUMN($Q34:$AO34)<>COLUMN($Z$8))))} -> 13 | M34: =K34 -> 8 | N34: =L34*3+M34 -> 47 | O34: =N34*100/(24*3+10) -> 57.317073 | P34: =(O34-$O$62)/$O$63 -> -0.080256836 | Q34: A | R34: C | S34: E | T34: C | U34: C | V34: C | W34: B | X34: D | Y34: C | Z34: A | AA34: C | AB34: B | AC34: C | AD34: C | AE34: C | AF34: D | AG34: C | AH34: A | AI34: B | AJ34: C | AK34: D | AL34: D | AM34: B | AN34: D | AO34: C | AP34: A | AQ34: B | AR34: A | AS34: A | AT34: A | AU34: A | AV34: B | AW34: B | AX34: A | AY34: B
A35: A | B35: =A35 -> A | C35: 891883 | D35: 891883 | E35: =_xlfn.XLOOKUP(D35,'Student Roster'!A:A,'Student Roster'!B:B, "Not Found") -> Sarkisyan, Rita | F35: =_xlfn.XLOOKUP(D35,'Student Roster'!A:A,'Student Roster'!C:C, "Not Found") -> 43957 | G35: Sarkisyan, Rita | H35: 43957 | J35: {=SUMPRODUCT(--(Q35:AO35=IF(B35="A",$Q$5:$AO$5,$Q$6:$AO$6)))} -> 4 | K35: {=SUMPRODUCT(--(AP35:AY35=IF(B35="A",$AP$5:$AY$5,$AP$6:$AY$6)))} -> 9 | L35: {=SUMPRODUCT(--($Q35:$AO35 = IF($B35="A", $Q$5:$AO$5, $Q$6:$AO$6)),--IF($B35="A", (COLUMN($Q35:$AO35)<>COLUMN($W$8)), (COLUMN($Q35:$AO35)<>COLUMN($Z$8))))} -> 4 | M35: =K35 -> 9 | N35: =L35*3+M35 -> 21 | O35: =N35*100/(24*3+10) -> 25.609756 | P35: =(O35-$O$62)/$O$63 -> -1.8590641 | Q35: D | R35: C | S35: B | T35: E | U35: C | V35: D | W35: A | X35: D | Y35: B | Z35: C | AA35: A | AB35: A | AC35: B | AD35: D | AE35: A | AF35: B | AG35: B | AH35: D | AI35: A | AJ35: B | AK35: C | AL35: D | AM35: A | AN35: E | AO35: A | AP35: A | AQ35: A | AR35: A | AS35: B | AT35: B | AU35: A | AV35: B | AW35: B | AX35: A | AY35: A
A36: A | B36: =A36 -> A | C36: 928878 | D36: 928878 | E36: =_xlfn.XLOOKUP(D36,'Student Roster'!A:A,'Student Roster'!B:B, "Not Found") -> Her, Kangbao | F36: =_xlfn.XLOOKUP(D36,'Student Roster'!A:A,'Student Roster'!C:C, "Not Found") -> 43958 | G36: Her, Kangbao | H36: 43958 | J36: {=SUMPRODUCT(--(Q36:AO36=IF(B36="A",$Q$5:$AO$5,$Q$6:$AO$6)))} -> 14 | K36: {=SUMPRODUCT(--(AP36:AY36=IF(B36="A",$AP$5:$AY$5,$AP$6:$AY$6)))} -> 7 | L36: {=SUMPRODUCT(--($Q36:$AO36 = IF($B36="A", $Q$5:$AO$5, $Q$6:$AO$6)),--IF($B36="A", (COLUMN($Q36:$AO36)<>COLUMN($W$8)), (COLUMN($Q36:$AO36)<>COLUMN($Z$8))))} -> 14 | M36: =K36 -> 7 | N36: =L36*3+M36 -> 49 | O36: =N36*100/(24*3+10) -> 59.756098 | P36: =(O36-$O$62)/$O$63 -> 0.056574491 | Q36: D | R36: A | S36: A | T36: E | U36: C | V36: D | W36: A | X36: B | Y36: B | Z36: D | AA36: C | AB36: D | AC36: C | AD36: A | AE36: C | AF36: B | AG36: B | AH36: B | AI36: B | AJ36: D | AK36: C | AL36: D | AM36: B | AN36: D | AO36: B | AP36: B | AQ36: A | AR36: A | AS36: B | AT36: B | AU36: A | AV36: B | AW36: A | AX36: A | AY36: A
A37: B | B37: =A37 -> B | C37: 523330 | D37: 523330 | E37: =_xlfn.XLOOKUP(D37,'Student Roster'!A:A,'Student Roster'!B:B, "Not Found") -> Pyle, Matthew | F37: =_xlfn.XLOOKUP(D37,'Student Roster'!A:A,'Student Roster'!C:C, "Not Found") -> 43957 | G37: Pyle, Matthew | H37: 43957 | J37: {=SUMPRODUCT(--(Q37:AO37=IF(B37="A",$Q$5:$AO$5,$Q$6:$AO$6)))} -> 16 | K37: {=SUMPRODUCT(--(AP37:AY37=IF(B37="A",$AP$5:$AY$5,$AP$6:$AY$6)))} -> 8 | L37: {=SUMPRODUCT(--($Q37:$AO37 = IF($B37="A", $Q$5:$AO$5, $Q$6:$AO$6)),--IF($B37="A", (COLUMN($Q37:$AO37)<>COLUMN($W$8)), (COLUMN($Q37:$AO37)<>COLUMN($Z$8))))} -> 16 | M37: =K37 -> 8 | N37: =L37*3+M37 -> 56 | O37: =N37*100/(24*3+10) -> 68.292683 | P37: =(O37-$O$62)/$O$63 -> 0.53548414 | Q37: A | R37: A | S37: C | T37: D | U37: E | V37: A | W37: C | X37: A | Y37: A | Z37: A | AA37: C | AB37: C | AC37: D | AD37: C | AE37: C | AF37: B | AG37: B | AH37: A | AI37: B | AJ37: C | AK37: D | AL37: A | AM37: A | AN37: D | AO37: B | AP37: A | AQ37: B | AR37: B | AS37: A | AT37: A | AU37: A | AV37: B | AW37: B | AX37: A | AY37: A
A38: B | B38: =A38 -> B | C38: 977589 | D38: 977589 | E38: =_xlfn.XLOOKUP(D38,'Student Roster'!A:A,'Student Roster'!B:B, "Not Found") -> Negrete, Miguel | F38: =_xlfn.XLOOKUP(D38,'Student Roster'!A:A,'Student Roster'!C:C, "Not Found") -> 43958 | G38: Negrete, Miguel | H38: 43958 | J38: {=SUMPRODUCT(--(Q38:AO38=IF(B38="A",$Q$5:$AO$5,$Q$6:$AO$6)))} -> 20 | K38: {=SUMPRODUCT(--(AP38:AY38=IF(B38="A",$AP$5:$AY$5,$AP$6:$AY$6)))} -> 6 | L38: {=SUMPRODUCT(--($Q38:$AO38 = IF($B38="A", $Q$5:$AO$5, $Q$6:$AO$6)),--IF($B38="A", (COLUMN($Q38:$AO38)<>COLUMN($W$8)), (COLUMN($Q38:$AO38)<>COLUMN($Z$8))))} -> 19 | M38: =K38 -> 6 | N38: =L38*3+M38 -> 63 | O38: =N38*100/(24*3+10) -> 76.829268 | P38: =(O38-$O$62)/$O$63 -> 1.0143938 | Q38: A | R38: A | S38: C | T38: D | U38: E | V38: B | W38: C | X38: D | Y38: C | Z38: C | AA38: C | AB38: C | AC38: B | AD38: C | AE38: C | AF38: A | AG38: B | AH38: B | AI38: B | AJ38: C | AK38: D | AL38: A | AM38: C | AN38: D | AO38: A | AP38: A | AQ38: B | AR38: A | AS38: A | AT38: A | AU38: B | AV38: B | AW38: B | AX38: A | AY38: A
A39: B | B39: =A39 -> B | C39: 790131 | D39: 790131 | E39: =_xlfn.XLOOKUP(D39,'Student Roster'!A:A,'Student Roster'!B:B, "Not Found") -> Garcia, Andres | F39: =_xlfn.XLOOKUP(D39,'Student Roster'!A:A,'Student Roster'!C:C, "Not Found") -> 43957 | G39: Garcia, Andres | H39: 43957 | J39: {=SUMPRODUCT(--(Q39:AO39=IF(B39="A",$Q$5:$AO$5,$Q$6:$AO$6)))} -> 17 | K39: {=SUMPRODUCT(--(AP39:AY39=IF(B39="A",$AP$5:$AY$5,$AP$6:$AY$6)))} -> 6 | L39: {=SUMPRODUCT(--($Q39:$AO39 = IF($B39="A", $Q$5:$AO$5, $Q$6:$AO$6)),--IF($B39="A", (COLUMN($Q39:$AO39)<>COLUMN($W$8)), (COLUMN($Q39:$AO39)<>COLUMN($Z$8))))} -> 16 | M39: =K39 -> 6 | N39: =L39*3+M39 -> 54 | O39: =N39*100/(24*3+10) -> 65.853659 | P39: =(O39-$O$62)/$O$63 -> 0.39865281 | Q39: A | R39: A | S39: C | T39: D | U39: E | V39: D | W39: C | X39: A | Y39: D | Z39: C | AA39: C | AB39: C | AC39: B | AD39: B | AE39: C | AF39: A | AG39: B | AH39: B | AI39: B | AJ39: B | AK39: D | AL39: C | AM39: C | AN39: D | AO39: B | AP39: A | AQ39: B | AR39: A | AS39: B | AT39: A | AU39: A | AV39: B | AW39: B | AX39: A | AY39: A
A40: A | B40: =A40 -> A | C40: 1038679 | D40: 1038679 | E40: =_xlfn.XLOOKUP(D40,'Student Roster'!A:A,'Student Roster'!B:B, "Not Found") -> Hernandez, Arriel | F40: =_xlfn.XLOOKUP(D40,'Student Roster'!A:A,'Student Roster'!C:C, "Not Found") -> 43958 | G40: Hernandez, Arriel | H40: 43958 | J40: {=SUMPRODUCT(--(Q40:AO40=IF(B40="A",$Q$5:$AO$5,$Q$6:$AO$6)))} -> 15 | K40: {=SUMPRODUCT(--(AP40:AY40=IF(B40="A",$AP$5:$AY$5,$AP$6:$AY$6)))} -> 4 | L40: {=SUMPRODUCT(--($Q40:$AO40 = IF($B40="A", $Q$5:$AO$5, $Q$6:$AO$6)),--IF($B40="A", (COLUMN($Q40:$AO40)<>COLUMN($W$8)), (COLUMN($Q40:$AO40)<>COLUMN($Z$8))))} -> 14 | M40: =K40 -> 4 | N40: =L40*3+M40 -> 46 | O40: =N40*100/(24*3+10) -> 56.097561 | P40: =(O40-$O$62)/$O$63 -> -0.1486725 | Q40: A | R40: A | S40: A | T40: C | U40: C | V40: C | W40: C | X40: C | Y40: C | Z40: D | AA40: C | AB40: B | AC40: C | AD40: A | AE40: A | AF40: C | AG40: C | AH40: D | AI40: D | AJ40: D | AK40: C | AL40: D | AM40: D | AN40: D | AO40: C | AP40: B | AQ40: A | AR40: B | AS40: B | AT40: B | AU40: B | AV40: B | AW40: A | AX40: B | AY40: A
A41: B | B41: =A41 -> B | C41: 684403 | D41: 684403 | E41: =_xlfn.XLOOKUP(D41,'Student Roster'!A:A,'Student Roster'!B:B, "Not Found") -> Morgan, Steven | F41: =_xlfn.XLOOKUP(D41,'Student Roster'!A:A,'Student Roster'!C:C, "Not Found") -> 43958 | G41: Morgan, Steven | H41: 43958 | J41: {=SUMPRODUCT(--(Q41:AO41=IF(B41="A",$Q$5:$AO$5,$Q$6:$AO$6)))} -> 18 | K41: {=SUMPRODUCT(--(AP41:AY41=IF(B41="A",$AP$5:$AY$5,$AP$6:$AY$6)))} -> 7 | L41: {=SUMPRODUCT(--($Q41:$AO41 = IF($B41="A", $Q$5:$AO$5, $Q$6:$AO$6)),--IF($B41="A", (COLUMN($Q41:$AO41)<>COLUMN($W$8)), (COLUMN($Q41:$AO41)<>COLUMN($Z$8))))} -> 17 | M41: =K41 -> 7 | N41: =L41*3+M41 -> 58 | O41: =N41*100/(24*3+10) -> 70.731707 | P41: =(O41-$O$62)/$O$63 -> 0.67231546 | Q41: C | R41: D | S41: C | T41: D | U41: C | V41: C | W41: B | X41: D | Y41: C | Z41: C | AA41: C | AB41: C | AC41: B | AD41: D | AE41: C | AF41: A | AG41: B | AH41: B | AI41: B | AJ41: C | AK41: D | AL41: D | AM41: A | AN41: D | AO41: C | AP41: A | AQ41: B | AR41: A | AS41: B | AT41: A | AU41: A | AV41: B | AW41: A | AX41: A | AY41: A
...

Sheet Sheet2
C1: Your Choices | D1: Key
B2: ="Q"&ROW()-1 -> Q1 | C2: B | D2: B | E2: =IF(C2=D2,"X","") -> X
B3: ="Q"&ROW()-1 -> Q2 | C3: A | D3: A | E3: =IF(C3=D3,"X","") -> X
B4: ="Q"&ROW()-1 -> Q3 | C4: B | D4: A | E4: =IF(C4=D4,"X","")
B5: ="Q"&ROW()-1 -> Q4 | C5: C | D5: C | E5: =IF(C5=D5,"X","") -> X
B6: ="Q"&ROW()-1 -> Q5 | C6: C | D6: C | E6: =IF(C6=D6,"X","") -> X
B7: ="Q"&ROW()-1 -> Q6 | C7: D | D7: D | E7: =IF(C7=D7,"X","") -> X
B8: ="Q"&ROW()-1 -> Q7 | C8: C | D8: C | E8: =IF(C8=D8,"X","") -> X
B9: ="Q"&ROW()-1 -> Q8 | C9: B | D9: C | E9: =IF(C9=D9,"X","")
B10: ="Q"&ROW()-1 -> Q9 | C10: B | D10: C | E10: =IF(C10=D10,"X","")
B11: ="Q"&ROW()-1 -> Q10 | C11: D | D11: D | E11: =IF(C11=D11,"X","") -> X
B12: ="Q"&ROW()-1 -> Q11 | C12: C | D12: C | E12: =IF(C12=D12,"X","") -> X
B13: ="Q"&ROW()-1 -> Q12 | C13: C | D13: C | E13: =IF(C13=D13,"X","") -> X
... B36: ="Q"&ROW()-1 -> Q35 | C36: B | D36: B | E36: =IF(C36=D36,"X","") -> X

Sheet For Canvas
A2: Student Name | B2: Section | C2: M/C Correct | D2: T/F Correct | E2: M/C Correct | F2: T/F Correct | G2: Raw Score | H2: Adjusted Score | J2: M/C Correct | K2: T/F Correct | L2: M/C Correct | M2: T/F Correct | N2: Raw Score | O2: Adjusted Score
A3: Andrade, Antonio | B3: 43957 | C3: 16 | D3: 8 | E3: 15 | F3: 8 | G3: 53 | H3: 64.634146 | J3: 17 | K3: 8 | L3: 16 | M3: 8 | N3: 56 | O3: 68.292683 | P3: =IF(O3>H3,"+",IF(O3<H3,"-",S3)) -> + | Q3: =IF(O3>H3,O3,H3) -> 68.292683 | R3: =(Q3-$Q$56)/$Q$57 -> 0.51800397 | S3: =IF(R3<=-2,"XXX",IF(AND(R3<=-1.5,R3>-2),"XX",IF(AND(R3<=-1,R3>-1.5),"X","")))
A4: Aquino, Hailey | B4: 43957 | C4: 23 | D4: 10 | E4: 22 | F4: 10 | G4: 76 | H4: 92.682927 | J4: 24 | K4: 10 | L4: 23 | M4: 10 | N4: 79 | O4: 96.341463 | P4: =IF(O4>H4,"+",IF(O4<H4,"-",S4)) -> + | Q4: =IF(O4>H4,O4,H4) -> 96.341463 | R4: =(Q4-$Q$56)/$Q$57 -> 2.0984447 | S4: =IF(R4<=-2,"XXX",IF(AND(R4<=-1.5,R4>-2),"XX",IF(AND(R4<=-1,R4>-1.5),"X","")))
A5: Arellano Cruz, Ashley | B5: 43958 | C5: 9 | D5: 5 | E5: 9 | F5: 5 | G5: 32 | H5: 39.02439 | J5: 8 | K5: 5 | L5: 8 | M5: 5 | N5: 29 | O5: 35.365854 | P5: =IF(O5>H5,"+",IF(O5<H5,"-",S5)) -> - | Q5: =IF(O5>H5,O5,H5) -> 39.02439 | R5: =(Q5-$Q$56)/$Q$57 -> -1.1311515 | S5: =IF(R5<=-2,"XXX",IF(AND(R5<=-1.5,R5>-2),"XX",IF(AND(R5<=-1,R5>-1.5),"X",""))) -> X
A6: Becerril, Destiny | B6: 43958 | C6: 13 | D6: 4 | E6: 12 | F6: 4 | G6: 40 | H6: 48.780488 | J6: 12 | K6: 4 | L6: 11 | M6: 4 | N6: 37 | O6: 45.121951 | P6: =IF(O6>H6,"+",IF(O6<H6,"-",S6)) -> - | Q6: =IF(O6>H6,O6,H6) -> 48.780488 | R6: =(Q6-$Q$56)/$Q$57 -> -0.58143303 | S6: =IF(R6<=-2,"XXX",IF(AND(R6<=-1.5,R6>-2),"XX",IF(AND(R6<=-1,R6>-1.5),"X","")))
A7: Bryant, Tajanique | B7: 43958 | C7: 14 | D7: 7 | E7: 13 | F7: 7 | G7: 46 | H7: 56.097561 | J7: 15 | K7: 7 | L7: 14 | M7: 7 | N7: 49 | O7: 59.756098 | P7: =IF(O7>H7,"+",IF(O7<H7,"-",S7)) -> + | Q7: =IF(O7>H7,O7,H7) -> 59.756098 | R7: =(Q7-$Q$56)/$Q$57 -> 0.037000284 | S7: =IF(R7<=-2,"XXX",IF(AND(R7<=-1.5,R7>-2),"XX",IF(AND(R7<=-1,R7>-1.5),"X","")))
A8: Castro, Socorro | B8: 43958 | C8: 11 | D8: 8 | E8: 10 | F8: 8 | G8: 38 | H8: 46.341463 | J8: 12 | K8: 8 | L8: 11 | M8: 8 | N8: 41 | O8: 50 | P8: =IF(O8>H8,"+",IF(O8<H8,"-",S8)) -> + | Q8: =IF(O8>H8,O8,H8) -> 50 | R8: =(Q8-$Q$56)/$Q$57 -> -0.51271822 | S8: =IF(R8<=-2,"XXX",IF(AND(R8<=-1.5,R8>-2),"XX",IF(AND(R8<=-1,R8>-1.5),"X","")))
A9: Ceballos, Ariel | B9: 43957 | C9: 17 | D9: 8 | E9: 17 | F9: 8 | G9: 59 | H9: 71.95122 | J9: 18 | K9: 8 | L9: 18 | M9: 8 | N9: 62 | O9: 75.609756 | P9: =IF(O9>H9,"+",IF(O9<H9,"-",S9)) -> + | Q9: =IF(O9>H9,O9,H9) -> 75.609756 | R9: =(Q9-$Q$56)/$Q$57 -> 0.93029285 | S9: =IF(R9<=-2,"XXX",IF(AND(R9<=-1.5,R9>-2),"XX",IF(AND(R9<=-1,R9>-1.5),"X","")))
A10: Corea, Kristie | B10: 43957 | C10: 11 | D10: 5 | E10: 10 | F10: 5 | G10: 35 | H10: 42.682927 | J10: 12 | K10: 5 | L10: 11 | M10: 5 | N10: 38 | O10: 46.341463 | P10: =IF(O10>H10,"+",IF(O10<H10,"-",S10)) -> + | Q10: =IF(O10>H10,O10,H10) -> 46.341463 | R10: =(Q10-$Q$56)/$Q$57 -> -0.71886266 | S10: =IF(R10<=-2,"XXX",IF(AND(R10<=-1.5,R10>-2),"XX",IF(AND(R10<=-1,R10>-1.5),"X","")))
A11: Cuevas Romero, Ana | B11: 43957 | C11: 23 | D11: 9 | E11: 22 | F11: 9 | G11: 75 | H11: 91.463415 | J11: 24 | K11: 9 | L11: 23 | M11: 9 | N11: 78 | O11: 95.121951 | P11: =IF(O11>H11,"+",IF(O11<H11,"-",S11)) -> + | Q11: =IF(O11>H11,O11,H11) -> 95.121951 | R11: =(Q11-$Q$56)/$Q$57 -> 2.0297299 | S11: =IF(R11<=-2,"XXX",IF(AND(R11<=-1.5,R11>-2),"XX",IF(AND(R11<=-1,R11>-1.5),"X","")))
A12: Fang, Pa | B12: 43957 | C12: 7 | D12: 5 | E12: 7 | F12: 5 | G12: 26 | H12: 31.707317 | J12: 8 | K12: 5 | L12: 8 | M12: 5 | N12: 29 | O12: 35.365854 | P12: =IF(O12>H12,"+",IF(O12<H12,"-",S12)) -> + | Q12: =IF(O12>H12,O12,H12) -> 35.365854 | R12: =(Q12-$Q$56)/$Q$57 -> -1.337296 | S12: =IF(R12<=-2,"XXX",IF(AND(R12<=-1.5,R12>-2),"XX",IF(AND(R12<=-1,R12>-1.5),"X",""))) -> X
A13: Gamez, Sergio | B13: 43957 | C13: 14 | D13: 8 | E13: 13 | F13: 8 | G13: 47 | H13: 57.317073 | J13: 15 | K13: 8 | L13: 14 | M13: 8 | N13: 59.8 | O13: 60.97561 | P13: =IF(O13>H13,"+",IF(O13<H13,"-",S13)) -> + | Q13: =IF(O13>H13,O13,H13) -> 60.97561 | R13: =(Q13-$Q$56)/$Q$57 -> 0.1057151 | S13: =IF(R13<=-2,"XXX",IF(AND(R13<=-1.5,R13>-2),"XX",IF(AND(R13<=-1,R13>-1.5),"X","")))
A14: Garcia, Andres | B14: 43957 | C14: 18 | D14: 6 | E14: 17 | F14: 6 | G14: 57 | H14: 69.512195 | J14: 17 | K14: 6 | L14: 16 | M14: 6 | N14: 53.7 | O14: 65.853659 | P14: =IF(O14>H14,"+",IF(O14<H14,"-",S14)) -> - | Q14: =IF(O14>H14,O14,H14) -> 69.512195 | R14: =(Q14-$Q$56)/$Q$57 -> 0.58671879 | S14: =IF(R14<=-2,"XXX",IF(AND(R14<=-1.5,R14>-2),"XX",IF(AND(R14<=-1,R14>-1.5),"X","")))
... A54: Zavala, Nia | B54: 43958 | C54: 16 | D54: 2 | E54: 15 | F54: 2 | G54: 47 | H54: 57.317073 | J54: 17 | K54: 2 | L54: 16 | M54: 2 | N54: 50 | O54: 60.97561 | P54: =IF(O54>H54,"+",IF(O54<H54,"-",S54)) -> + | Q54: =IF(O54>H54,O54,H54) -> 60.97561 | R54: =(Q54-$Q$56)/$Q$57 -> 0.1057151 | S54: =IF(R54<=-2,"XXX",IF(AND(R54<=-1.5,R54>-2),"XX",IF(AND(R54<=-1,R54>-1.5),"X","")))
P56: mean | Q56: =AVERAGE(Q3:Q54) -> 59.099437
P57: std dev | Q57: =_xlfn.STDEV.P(Q3:Q54) -> 17.747443

Sheet I have two PDFs I am uploading 
A1: Version A Question | B1: Version A Content (Short Description) | C1: Version B Question | E1: Question | F1: Version A | G1: Explanation
A2: 1 | B2: Order of strength of intermolecular forces (H-B>D-D>LDF) | C2: 18 | E2: 1 | F2: b) H-B>D-D>LDF | G2: The order of strength is: Hydrogen Bonding (H-B, strongest) > Dipole-Dipole (D-D, intermediate) > London Dispersion Forces (LDF, weakest).
A3: 2 | B3: Mass of sulfur, units for "10.0" (g) | C3: 1 | E3: 2 | F3: a) g | G3: Mass is a measure of the amount of matter and is correctly expressed in grams (g).
A4: 3 | B4: Change in enthalpy when a substance is boiled (ΔHvap​) | C4: 2 | E4: 3 | F4: a) ΔHvap​ | G4: Boiling is the phase change from liquid to gas (vaporization), and the associated enthalpy change is the enthalpy of vaporization (ΔHvap​).
A5: 4 | B5: Type of matter with definite volume and definite shape (solid) | C5: 3 | E5: 4 | F5: c) solid | G5: A solid has both a definite volume and a definite shape.
A6: 5 | B6: Heat energy transferred to Cd metal (q=m×c×ΔT) | C6: 7 | E6: 5 | F6: c) 75.0 J | G6: Use the heat formula q=m×c×ΔT. q=(10.0 g)×(0.250 J/(g∘C))×(50∘C−20∘C) q=(10.0 g)×(0.250 J/(g∘C))×(30∘C)=75.0 J
A7: 6 | B7: Characteristics of a Type II ion (transition metal, multiple charge states, uses Roman numeral) | C7: 8 | E7: 6 | F7: d) all the above | G7: A Type II ion is a positively charged metal cation (a transition metal) that can form more than one charge state , and its name in a compound requires a Roman numeral (Stock system).
A8: 7 | B8: Step to complete Lewis structure of (CO3​)2− (create double bond) (NOTE: Question text has error, uses NO3−​ and central N/C atom) | C8: 10 | E8: 7 | F8: c) A lone pair from one of the oxygen (O) atoms will have to be used to create a double bond with the central nitrogen (N) | G8: To complete the octet on the central atom when no electrons are left in the inventory, you must form a double bond using one of the lone pairs from a terminal atom. (Note: The question is confusingly written, referring to the NO3−​ ion but calling the central atom "carbon (N)").
A9: 8 | B9: Molar mass of MgSO4​⋅7H2​O (246.5 g/mol) | C9: 11 | E9: 8 | F9: c) 246.5 g/mol | G9: The molar mass of MgSO4​⋅7H2​O is calculated by summing the molar masses: Mg+S+(4×O)+7×[(2×H)+O]. 24.31+32.07+(4×16.00)+7×(18.02)≈246.5 g/mol.
A10: 9 | B10: Mass percentage of water in hydrate MgSO4​⋅7H2​O (51.16%) | C10: 12 | E10: 9 | F10: c) 51.16% | G10: The mass percentage of water is Molar mass of HydrateMass of 7H2​O​×100%. Mass of 7H2​O=7×18.02 g/mol≈126.14 g/mol. Mass Percentage=246.5 g/mol126.14 g/mol​×100%≈51.17% (which matches option c) 51.16%).
A11: 10 | B11: Total valence electrons for NO2−​ ion (18) | C11: 4 | E11: 10 | F11: d) 18 | G11: The total number of valence electrons for the NO2−​ ion is: Nitrogen (Group 15) has 5 e−. Oxygen (Group 16) has 6 e−. Charge (-1) adds 1 e−. 5+(2×6)+1=∗∗18∗∗ valence electrons.
A12: 11 | B12: Number of electrons in an octet (8) | C12: 5 | E12: 11 | F12: e) 8 | G12: A stable electron configuration, or octet, means the atom is surrounded by 8 valence electrons.
A13: 12 | B13: False statement about NO2−​ Lewis structure (Central N has no lone pairs) | C13: 6 | E13: 12 | F13: c) The central atom nitrogen has no nonbonding (lone) pairs of electrons | G13: The Lewis structure for NO2−​ shown in the text (though incorrectly drawn as [:O−N=O:]−) or the correct resonance structure [O¨=N¨−O¨:]− both show the central Nitrogen atom with one nonbonding (lone) pair of electrons. Therefore, the statement that it has no lone pairs is FALSE.
... A36: 35 | B36: Cesium chloride formula is Cs2​Cl (false, it's CsCl) | C36: 35 | E36: 35 | F36: b) false | G36: Cesium (Cs) is Group 1 (+1 charge) and Chloride (Cl) is Group 17 (−1 charge). They combine in a 1:1 ratio to form the ionic compound CsCl. The formula Cs2​Cl is incorrect.
E38: Question | F38: Version B
E39: 1 | F39: =F3 -> a) g | G39: =G3 -> Mass is a measure of the amount of matter and is correctly expressed in grams (g).
E40: 2 | F40: =F4 -> a) ΔHvap​ | G40: =G4 -> Boiling is the phase change from liquid to gas (vaporization), and the associated enthalpy change is the enthalpy of vaporization (ΔHvap​).
E41: 3 | F41: =F5 -> c) solid | G41: =G5 -> A solid has both a definite volume and a definite shape.
E42: 4 | F42: =F11 -> d) 18 | G42: =G11 -> The total number of valence electrons for the NO2−​ ion is: Nitrogen (Group 15) has 5 e−. Oxygen (Group 16) has 6 e−. Charge (-1) adds 1 e−. 5+(2×6)+1=∗∗18∗∗ valence electrons.
E43: 5 | F43: =F12 -> e) 8 | G43: =G12 -> A stable electron configuration, or octet, means the atom is surrounded by 8 valence electrons.
E44: 6 | F44: =F13 -> c) The central atom nitrogen has no nonbonding (lone) pairs of electrons | G44: =G13 -> The Lewis structure for NO2−​ shown in the text (though incorrectly drawn as [:O−N=O:]−) or the correct resonance structure [O¨=N¨−O¨:]− both show the central Nitrogen atom with one nonbonding (lone) pair of electrons. Therefore, the statement that it has no lone pairs is FALSE.
E45: 7 | F45: =F6 -> c) 75.0 J | G45: =G6 -> Use the heat formula q=m×c×ΔT. q=(10.0 g)×(0.250 J/(g∘C))×(50∘C−20∘C) q=(10.0 g)×(0.250 J/(g∘C))×(30∘C)=75.0 J
E46: 8 | F46: =F7 -> d) all the above | G46: =G7 -> A Type II ion is a positively charged metal cation (a transition metal) that can form more than one charge state , and its name in a compound requires a Roman numeral (Stock system).
E47: 9 | F47: =F15 -> c) (nonpolar) covalent | G47: =G15 -> A very little difference in electronegativity between atoms results in an even sharing of electrons, forming a nonpolar covalent bond.
E48: 10 | F48: =F8 -> c) A lone pair from one of the oxygen (O) atoms will have to be used to create a double bond with the central nitrogen (N)
E49: 11 | F49: =F9 -> c) 246.5 g/mol | G49: =G9 -> The molar mass of MgSO4​⋅7H2​O is calculated by summing the molar masses: Mg+S+(4×O)+7×[(2×H)+O]. 24.31+32.07+(4×16.00)+7×(18.02)≈246.5 g/mol.
E50: 12 | F50: =F10 -> c) 51.16% | G50: =G10 -> The mass percentage of water is Molar mass of HydrateMass of 7H2​O​×100%. Mass of 7H2​O=7×18.02 g/mol≈126.14 g/mol. Mass Percentage=246.5 g/mol126.14 g/mol​×100%≈51.17% (which matches option c) 51.16%).
E51: 13 | F51: =F16 -> d) molecular | G51: =G16 -> H2​O (ice), CO2​ (dry ice), and I2​ are all formed from distinct, neutral molecules held together by intermolecular forces (H-bonding, LDF). This makes them molecular solids.
E52: 14 | F52: =F14 -> c) trigonal pyramidal | G52: =G14 -> NH3​ has a central N atom with three bonding pairs (to H atoms) and one nonbonding (lone) pair of electrons. This AX3​E configuration results in a trigonal pyramidal molecular geometry.
E53: 15 | F53: =F17 -> c) 274 K | G53: =G17 -> To convert from Celsius to Kelvin, use the formula K=∘C+273.15. K=1∘C+273≈274 K
E54: 16 | F54: =F18 -> a) ionic | G54: =G18 -> The largest difference in electronegativity (like between the metal Cs and the nonmetal F) results in a transfer of electrons and the formation of an ionic bond.
E55: 17 | F55: =F19 -> b) 2 mol | G55: =G19 -> Avogadro's Number (6.022×1023) is defined as the number of particles in one mole. If you have two (2) times Avogadro's Number of particles, you have 2 moles.
E56: 18 | F56: =F2 -> b) H-B>D-D>LDF | G56: =G2 -> The order of strength is: Hydrogen Bonding (H-B, strongest) > Dipole-Dipole (D-D, intermediate) > London Dispersion Forces (LDF, weakest).
E57: 19 | F57: =F20 -> b) elemental analysis | G57: =G20 -> Elemental analysis is the laboratory procedure used to determine the mass percent of each element in a compound, which is the key information needed to calculate the empirical formula.
E58: 20 | F58: =F22 -> c) iron(III) oxide | G58: =G22 -> Oxygen always has a charge of −2. The total negative charge is 3×(−2)=−6. To balance this, the two iron (Fe) atoms must have a total charge of +6, so each Fe must be Fe3+. This is named iron(III) oxide.
E59: 21 | F59: d) N2Cl4 | G59: =G23 -> The prefix "dinitrogen" means 2 nitrogen atoms (N2​). The prefix "tetrachloride" means 4 chlorine atoms (Cl4​). The correct formula should be N2​Cl4​. Since this is not an option, and N2​Cl2​ is listed as an option, this suggests a likely typo in the question or options. Assuming the question meant dinitrogen dichloride, the answer would be N2​Cl2​. If the question name is strictly correct (N2​Cl4​), a correct option is missing. Given the choices, b) N2​Cl2​ is the most plausible intended answer structure if an error occurred in either the name or options.
E60: 22 | F60: =F21 -> d) dipole-dipole interaction | G60: =G21 -> A dipole-dipole interaction is an electrostatic force between molecules that have a permanent partial positive charge (δ+) on one end and a partial negative charge (δ−) on the other, meaning they have a permanent dipole moment.
E61: 23 | F61: =F24 -> c) 40.08 g | G61: =G24 -> The molar mass of calcium (Ca) is 40.08 g/mol. Since 6.022×1023 atoms is the definition of 1 mole, then 1 mol of Ca has a mass equal to its molar mass.
E62: 24 | F62: =F25 -> d) both (b) and (c) | G62: =G25 -> Group 2 elements are the alkaline earth metals. Both Calcium (Ca) and Magnesium (Mg) are in Group 2. Sodium (Na) is in Group 1.
E63: 25 | F63: =F26 -> b) The difference in electronegativity between O and H atoms enables hydrogen bonding | G63: =G26 -> Hydrogen bonding is a special, strong dipole-dipole force enabled by the large electronegativity difference between H and highly electronegative atoms like O, N, or F.
...

Sheet Student Roster
A1: Count = | B1: =COUNTA(B3:B58) -> 56
A2: ID1 | B2: Student | C2: Section | D2: Email | F2: ID1 | G2: Student | H2: Section | I2: Email
A3: 694264 | B3: Andrade, Antonio | C3: 43957 | D3: AAndrade26@MY.SCCCD.EDU | F3: 345856 | G3: Marquez, Rocelia | H3: 43957 | I3: RMarquez33@MY.SCCCD.EDU
A4: 873290 | B4: Aquino, Hailey | C4: 43957 | D4: HJAquino1@MY.SCCCD.EDU | F4: 490011 | G4: Garcia, Sabrina | H4: 43957 | I4: SRGarcia4@MY.SCCCD.EDU
A5: 1016534 | B5: Arellano Cruz, Ashley | C5: 43958 | D5: AMArellanoCruz1@MY.SCCCD.EDU | F5: 517817 | G5: Torrence, Mykhail | H5: 43957 | I5: MTorrence1@MY.SCCCD.EDU
A6: 1070102 | B6: Becerril, Destiny | C6: 43958 | D6: DVBecerril1@MY.SCCCD.EDU | F6: 523330 | G6: Pyle, Matthew | H6: 43957 | I6: MPyle1@MY.SCCCD.EDU
A7: 759215 | B7: Castro, Socorro | C7: 43958 | D7: SCastro42@MY.SCCCD.EDU | F7: 547169 | G7: San Roman, Jesus | H7: 43958 | I7: JSanRoman2@MY.SCCCD.EDU
A8: 576373 | B8: Ceballos, Ariel | C8: 43957 | D8: AMCeballos1@MY.SCCCD.EDU | F8: 574404 | G8: Rodriguez, Madison | H8: 43958 | I8: MTRodriguez3@MY.SCCCD.EDU
A9: 994114 | B9: Corea, Kristie | C9: 43957 | D9: KNCorea1@MY.SCCCD.EDU | F9: 576373 | G9: Ceballos, Ariel | H9: 43957 | I9: AMCeballos1@MY.SCCCD.EDU
A10: 1024952 | B10: Cuevas Romero, Ana | C10: 43957 | D10: ADCuevasRomero1@MY.SCCCD.EDU | F10: 684403 | G10: Morgan, Steven | H10: 43958 | I10: SVMorgan1@MY.SCCCD.EDU
A11: 888543 | B11: Esparza, Beatrice | C11: 43957 | D11: BMEsparza1@MY.SCCCD.EDU | F11: 694264 | G11: Andrade, Antonio | H11: 43957 | I11: AAndrade26@MY.SCCCD.EDU
A12: 737921 | B12: Fang, Pa | C12: 43957 | D12: PHFang1@MY.SCCCD.EDU | F12: 737921 | G12: Fang, Pa | H12: 43957 | I12: PHFang1@MY.SCCCD.EDU
A13: 1039936 | B13: Gamez, Sergio | C13: 43957 | D13: SRGamez1@MY.SCCCD.EDU | F13: 754151 | G13: Zavala, Nia | H13: 43958 | I13: NRZavala2@MY.SCCCD.EDU
A14: 790131 | B14: Garcia, Andres | C14: 43957 | D14: AGarcia679@MY.SCCCD.EDU | F14: 759215 | G14: Castro, Socorro | H14: 43958 | I14: SCastro42@MY.SCCCD.EDU
... A58: 754151 | B58: Zavala, Nia | C58: 43958 | D58: NRZavala2@MY.SCCCD.EDU | F58: 1070102 | G58: Becerril, Destiny | H58: 43958 | I58: DVBecerril1@MY.SCCCD.EDU
