Workbook

Sheet Raw Analysis
J1: Key ID
H2: Answers | J2: A | L2: A | M2: D | N2: C | O2: B | P2: B | Q2: B | R2: D | S2: C | T2: C | U2: A | V2: D | W2: B | X2: C | Y2: B | Z2: B | AA2: A | AB2: C | AC2: A | AD2: C | AE2: C | AF2: D | AG2: D | AH2: C | AI2: B | AJ2: B | AK2: B | AL2: A | AM2: A | AN2: B | AO2: A | AP2: A | AQ2: B | AR2: A | AS2: B | AT2: A
E3: Full Test | J3: B | L3: B | M3: A | N3: D | O3: B | P3: C | Q3: B | R3: D | S3: C | T3: C | U3: A | V3: A | W3: D | X3: C | Y3: B | Z3: B | AA3: C | AB3: B | AC3: A | AD3: C | AE3: C | AF3: B | AG3: C | AH3: D | AI3: D | AJ3: B | AK3: B | AL3: A | AM3: A | AN3: B | AO3: A | AP3: A | AQ3: B | AR3: A | AS3: B | AT3: A
E4: M/C Correct | F4: T/F Correct | G4: Raw Score | H4: Adjusted Score | I4: Z value | J4: Recorded Key ID | K4: Edited Key ID
A5: ID1 | B5: Student | C5: Section | D5: Email | L5: Q. 1 | M5: Q. 2 | N5: Q. 3 | O5: Q. 4 | P5: Q. 5 | Q5: Q. 6 | R5: Q. 7 | S5: Q. 8 | T5: Q. 9 | U5: Q. 10 | V5: Q. 11 | W5: Q. 12 | X5: Q. 13 | Y5: Q. 14 | Z5: Q. 15 | AA5: Q. 16 | AB5: Q. 17 | AC5: Q. 18 | AD5: Q. 19 | AE5: Q. 20 | AF5: Q. 21 | AG5: Q. 22 | AH5: Q. 23 | AI5: Q. 24 | AJ5: Q. 25 | AK5: Q. 26 | AL5: Q. 27 | AM5: Q. 28 | AN5: Q. 29 | AO5: Q. 30 | AP5: Q. 31 | AQ5: Q. 32 | AR5: Q. 33 | AS5: Q. 34 | AT5: Q. 35
A6: 345856 | B6: Marquez, Rocelia | C6: 43957 | D6: RMarquez33@MY.SCCCD.EDU | E6: {=SUMPRODUCT(--(L6:AJ6=IF(K6="A",$L$2:$AJ$2,$L$3:$AJ$3)))} -> 9 | F6: {=SUMPRODUCT(--(AK6:AT6=IF(K6="A",$AK$2:$AT$2,$AK$3:$AT$3)))} -> 8 | G6: =E6*3+F6 -> 35 | H6: =G6*100/85 -> 41.176471 | I6: =(H6-$H$58)/$H$59 -> -0.88269422 | J6: B | K6: B | L6: A | M6: C | N6: D | O6: B | P6: B | Q6: D | R6: B | S6: D | T6: D | U6: D | V6: C | W6: D | X6: C | Y6: A | Z6: B | AA6: A | AB6: C | AC6: A | AD6: D | AE6: C | AF6: A | AG6: A | AH6: D | AI6: D | AJ6: E | AK6: B | AL6: A | AM6: A | AN6: B | AO6: B | AP6: A | AQ6: A | AR6: A | AS6: B | AT6: A
A7: 490011 | B7: Garcia, Sabrina | C7: 43957 | D7: SRGarcia4@MY.SCCCD.EDU | E7: {=SUMPRODUCT(--(L7:AJ7=IF(K7="A",$L$2:$AJ$2,$L$3:$AJ$3)))} -> 10 | F7: {=SUMPRODUCT(--(AK7:AT7=IF(K7="A",$AK$2:$AT$2,$AK$3:$AT$3)))} -> 3 | G7: =E7*3+F7 -> 33 | H7: =G7*100/85 -> 38.823529 | I7: =(H7-$H$58)/$H$59 -> -1.0043629 | J7: B | K7: B | L7: A | M7: A | N7: D | O7: B | P7: A | Q7: B | R7: D | S7: B | T7: B | U7: C | V7: B | W7: A | X7: C | Y7: D | Z7: B | AA7: A | AB7: C | AC7: C | AD7: A | AE7: C | AF7: E | AG7: B | AH7: A | AI7: D | AJ7: B | AK7: A | AL7: B | AM7: A | AN7: A | AO7: A | AP7: A | AQ7: A | AR7: B | AS7: A | AT7: B
A8: 523330 | B8: Pyle, Matthew | C8: 43957 | D8: MPyle1@MY.SCCCD.EDU | E8: {=SUMPRODUCT(--(L8:AJ8=IF(K8="A",$L$2:$AJ$2,$L$3:$AJ$3)))} -> 15 | F8: {=SUMPRODUCT(--(AK8:AT8=IF(K8="A",$AK$2:$AT$2,$AK$3:$AT$3)))} -> 8 | G8: =E8*3+F8 -> 53 | H8: =G8*100/85 -> 62.352941 | I8: =(H8-$H$58)/$H$59 -> 0.21232374 | J8: B | K8: B | L8: B | M8: A | N8: D | O8: B | P8: A | Q8: B | R8: A | S8: C | T8: C | U8: C | V8: A | W8: C | X8: C | Y8: A | Z8: B | AA8: A | AB8: B | AC8: A | AD8: D | AE8: A | AF8: B | AG8: C | AH8: A | AI8: C | AJ8: B | AK8: B | AL8: A | AM8: B | AN8: B | AO8: B | AP8: A | AQ8: B | AR8: A | AS8: B | AT8: A
A9: 547169 | B9: San Roman, Jesus | C9: 43958 | D9: JSanRoman2@MY.SCCCD.EDU | E9: {=SUMPRODUCT(--(L9:AJ9=IF(K9="A",$L$2:$AJ$2,$L$3:$AJ$3)))} -> 18 | F9: {=SUMPRODUCT(--(AK9:AT9=IF(K9="A",$AK$2:$AT$2,$AK$3:$AT$3)))} -> 9 | G9: =E9*3+F9 -> 63 | H9: =G9*100/85 -> 74.117647 | I9: =(H9-$H$58)/$H$59 -> 0.82066706 | J9: A | K9: A | L9: A | M9: A | N9: D | O9: B | P9: B | Q9: B | R9: D | S9: C | T9: C | U9: A | V9: B | W9: B | X9: C | Y9: A | Z9: B | AA9: A | AB9: A | AC9: A | AD9: C | AE9: B | AF9: D | AG9: D | AH9: C | AI9: A | AJ9: B | AK9: B | AL9: B | AM9: A | AN9: B | AO9: A | AP9: A | AQ9: B | AR9: A | AS9: B | AT9: A
A10: 574404 | B10: Rodriguez, Madison | C10: 43958 | D10: MTRodriguez3@MY.SCCCD.EDU | E10: {=SUMPRODUCT(--(L10:AJ10=IF(K10="A",$L$2:$AJ$2,$L$3:$AJ$3)))} -> 10 | F10: {=SUMPRODUCT(--(AK10:AT10=IF(K10="A",$AK$2:$AT$2,$AK$3:$AT$3)))} -> 8 | G10: =E10*3+F10 -> 38 | H10: =G10*100/85 -> 44.705882 | I10: =(H10-$H$58)/$H$59 -> -0.70019122 | J10: B | K10: B | L10: A | M10: C | N10: E | O10: B | P10: D | Q10: C | R10: D | S10: C | T10: C | U10: B | V10: A | W10: A | X10: D | Y10: D | Z10: B | AA10: C | AB10: A | AC10: C | AD10: B | AE10: C | AF10: A | AG10: B | AH10: D | AI10: D | AJ10: A | AK10: B | AL10: A | AM10: A | AN10: A | AO10: B | AP10: A | AQ10: B | AR10: A | AS10: B | AT10: A
A11: 576373 | B11: Ceballos, Ariel | C11: 43957 | D11: AMCeballos1@MY.SCCCD.EDU | E11: {=SUMPRODUCT(--(L11:AJ11=IF(K11="A",$L$2:$AJ$2,$L$3:$AJ$3)))} -> 15 | F11: {=SUMPRODUCT(--(AK11:AT11=IF(K11="A",$AK$2:$AT$2,$AK$3:$AT$3)))} -> 8 | G11: =E11*3+F11 -> 53 | H11: =G11*100/85 -> 62.352941 | I11: =(H11-$H$58)/$H$59 -> 0.21232374 | J11: B | K11: B | L11: B | M11: A | N11: D | O11: B | P11: D | Q11: B | R11: D | S11: C | T11: D | U11: C | V11: A | W11: D | X11: C | Y11: B | Z11: B | AA11: B | AB11: B | AC11: C | AD11: C | AE11: A | AF11: A | AG11: B | AH11: D | AI11: A | AJ11: A | AK11: B | AL11: B | AM11: A | AN11: B | AO11: A | AP11: B | AQ11: B | AR11: A | AS11: B | AT11: A | AW11: =0.08205*273/100 -> 0.2239965
A12: 684403 | B12: Morgan, Steven | C12: 43958 | D12: SVMorgan1@MY.SCCCD.EDU | E12: {=SUMPRODUCT(--(L12:AJ12=IF(K12="A",$L$2:$AJ$2,$L$3:$AJ$3)))} -> 17 | F12: {=SUMPRODUCT(--(AK12:AT12=IF(K12="A",$AK$2:$AT$2,$AK$3:$AT$3)))} -> 10 | G12: =E12*3+F12 -> 61 | H12: =G12*100/85 -> 71.764706 | I12: =(H12-$H$58)/$H$59 -> 0.69899839 | J12: A | K12: A | L12: B | M12: A | N12: C | O12: B | P12: B | Q12: B | R12: D | S12: C | T12: B | U12: A | V12: C | W12: B | X12: C | Y12: B | Z12: B | AA12: A | AB12: A | AC12: A | AD12: C | AE12: C | AF12: C | AG12: A | AH12: C | AI12: A | AJ12: B | AK12: B | AL12: A | AM12: A | AN12: B | AO12: A | AP12: A | AQ12: B | AR12: A | AS12: B | AT12: A
A13: 694264 | B13: Andrade, Antonio | C13: 43957 | D13: AAndrade26@MY.SCCCD.EDU | E13: {=SUMPRODUCT(--(L13:AJ13=IF(K13="A",$L$2:$AJ$2,$L$3:$AJ$3)))} -> 21 | F13: {=SUMPRODUCT(--(AK13:AT13=IF(K13="A",$AK$2:$AT$2,$AK$3:$AT$3)))} -> 10 | G13: =E13*3+F13 -> 73 | H13: =G13*100/85 -> 85.882353 | I13: =(H13-$H$58)/$H$59 -> 1.4290104 | J13: B | K13: B | L13: B | M13: A | N13: D | O13: B | P13: C | Q13: B | R13: D | S13: C | T13: B | U13: A | V13: A | W13: D | X13: C | Y13: B | Z13: B | AA13: C | AB13: B | AC13: A | AD13: C | AE13: C | AF13: B | AG13: B | AH13: D | AI13: A | AJ13: A | AK13: B | AL13: A | AM13: A | AN13: B | AO13: A | AP13: A | AQ13: B | AR13: A | AS13: B | AT13: A
A14: 737921 | B14: Fang, Pa | C14: 43957 | D14: PHFang1@MY.SCCCD.EDU | E14: {=SUMPRODUCT(--(L14:AJ14=IF(K14="A",$L$2:$AJ$2,$L$3:$AJ$3)))} -> 6 | F14: {=SUMPRODUCT(--(AK14:AT14=IF(K14="A",$AK$2:$AT$2,$AK$3:$AT$3)))} -> 5 | G14: =E14*3+F14 -> 23 | H14: =G14*100/85 -> 27.058824 | I14: =(H14-$H$58)/$H$59 -> -1.6127062 | J14: A | K14: A | L14: D | M14: E | N14: B | O14: B | P14: B | Q14: A | R14: B | S14: D | T14: D | U14: D | V14: B | W14: C | X14: C | Y14: D | Z14: B | AA14: C | AB14: B | AC14: C | AD14: C | AE14: B | AF14: D | AG14: A | AH14: B | AI14: E | AJ14: A | AK14: A | AL14: B | AM14: A | AN14: B | AO14: A | AP14: A | AQ14: A | AR14: B | AS14: B | AT14: B
A15: 754151 | B15: Zavala, Nia | C15: 43958 | D15: NRZavala2@MY.SCCCD.EDU | E15: {=SUMPRODUCT(--(L15:AJ15=IF(K15="A",$L$2:$AJ$2,$L$3:$AJ$3)))} -> 12 | F15: {=SUMPRODUCT(--(AK15:AT15=IF(K15="A",$AK$2:$AT$2,$AK$3:$AT$3)))} -> 7 | G15: =E15*3+F15 -> 43 | H15: =G15*100/85 -> 50.588235 | I15: =(H15-$H$58)/$H$59 -> -0.39601957 | J15: A | K15: A | L15: C | M15: C | N15: B | O15: B | P15: A | Q15: A | R15: D | S15: C | T15: C | U15: A | V15: B | W15: C | X15: C | Y15: B | Z15: B | AA15: C | AB15: C | AC15: C | AD15: C | AE15: A | AF15: A | AG15: A | AH15: C | AI15: B | AJ15: A | AK15: B | AL15: A | AM15: B | AN15: B | AO15: B | AP15: A | AQ15: A | AR15: A | AS15: B | AT15: A
A16: 759215 | B16: Castro, Socorro | C16: 43958 | D16: SCastro42@MY.SCCCD.EDU | E16: {=SUMPRODUCT(--(L16:AJ16=IF(K16="A",$L$2:$AJ$2,$L$3:$AJ$3)))} -> 22 | F16: {=SUMPRODUCT(--(AK16:AT16=IF(K16="A",$AK$2:$AT$2,$AK$3:$AT$3)))} -> 10 | G16: =E16*3+F16 -> 76 | H16: =G16*100/85 -> 89.411765 | I16: =(H16-$H$58)/$H$59 -> 1.6115134 | J16: B | K16: B | L16: B | M16: A | N16: D | O16: B | P16: C | Q16: B | R16: D | S16: C | T16: C | U16: A | V16: D | W16: D | X16: C | Y16: B | Z16: B | AA16: C | AB16: B | AC16: A | AD16: C | AE16: C | AF16: D | AG16: C | AH16: D | AI16: D | AJ16: A | AK16: B | AL16: A | AM16: A | AN16: B | AO16: A | AP16: A | AQ16: B | AR16: A | AS16: B | AT16: A
A17: 775232 | B17: Vargas, Lisa | C17: 43957 | D17: LRVargas1@MY.SCCCD.EDU | E17: {=SUMPRODUCT(--(L17:AJ17=IF(K17="A",$L$2:$AJ$2,$L$3:$AJ$3)))} -> 13 | F17: {=SUMPRODUCT(--(AK17:AT17=IF(K17="A",$AK$2:$AT$2,$AK$3:$AT$3)))} -> 10 | G17: =E17*3+F17 -> 49 | H17: =G17*100/85 -> 57.647059 | I17: =(H17-$H$58)/$H$59 -> -0.031013581 | J17: B | K17: B | L17: B | M17: A | N17: A | O17: B | P17: D | Q17: B | R17: B | S17: C | T17: C | U17: A | V17: A | W17: C | X17: C | Y17: D | Z17: D | AA17: D | AB17: D | AC17: A | AD17: A | AE17: A | AF17: B | AG17: C | AH17: D | AI17: B | AJ17: A | AK17: B | AL17: A | AM17: A | AN17: B | AO17: A | AP17: A | AQ17: B | AR17: A | AS17: B | AT17: A
A18: 790131 | B18: Garcia, Andres | C18: 43957 | D18: AGarcia679@MY.SCCCD.EDU | E18: {=SUMPRODUCT(--(L18:AJ18=IF(K18="A",$L$2:$AJ$2,$L$3:$AJ$3)))} -> 16 | F18: {=SUMPRODUCT(--(AK18:AT18=IF(K18="A",$AK$2:$AT$2,$AK$3:$AT$3)))} -> 8 | G18: =E18*3+F18 -> 56 | H18: =G18*100/85 -> 65.882353 | I18: =(H18-$H$58)/$H$59 -> 0.39482674 | J18: B | K18: B | L18: A | M18: B | N18: D | O18: B | P18: C | Q18: B | R18: D | S18: C | T18: C | U18: C | V18: A | W18: D | X18: C | Y18: A | Z18: B | AA18: C | AB18: B | AC18: C | AD18: B | AE18: C | AF18: A | AG18: B | AH18: D | AI18: D | AJ18: A | AK18: B | AL18: A | AM18: A | AN18: A | AO18: B | AP18: A | AQ18: B | AR18: A | AS18: B | AT18: A
A19: 792916 | B19: Parada, Jennifer | C19: 43958 | D19: JParada1@MY.SCCCD.EDU | E19: {=SUMPRODUCT(--(L19:AJ19=IF(K19="A",$L$2:$AJ$2,$L$3:$AJ$3)))} -> 18 | F19: {=SUMPRODUCT(--(AK19:AT19=IF(K19="A",$AK$2:$AT$2,$AK$3:$AT$3)))} -> 10 | G19: =E19*3+F19 -> 64 | H19: =G19*100/85 -> 75.294118 | I19: =(H19-$H$58)/$H$59 -> 0.88150139 | J19: A | K19: A | L19: A | M19: A | N19: C | O19: B | P19: B | Q19: B | R19: D | S19: C | T19: C | U19: A | V19: C | W19: B | X19: C | Y19: D | Z19: B | AA19: B | AB19: C | AC19: A | AD19: C | AE19: B | AF19: D | AG19: A | AH19: C | AI19: B | AJ19: A | AK19: B | AL19: A | AM19: A | AN19: B | AO19: A | AP19: A | AQ19: B | AR19: A | AS19: B | AT19: A
A20: 808147 | B20: Martinez, Vanessa | C20: 43958 | D20: VEMartinez2@MY.SCCCD.EDU | E20: {=SUMPRODUCT(--(L20:AJ20=IF(K20="A",$L$2:$AJ$2,$L$3:$AJ$3)))} -> 8 | F20: {=SUMPRODUCT(--(AK20:AT20=IF(K20="A",$AK$2:$AT$2,$AK$3:$AT$3)))} -> 6 | G20: =E20*3+F20 -> 30 | H20: =G20*100/85 -> 35.294118 | I20: =(H20-$H$58)/$H$59 -> -1.1868659 | J20: B | K20: B | L20: A | M20: C | N20: B | O20: B | P20: B | Q20: C | R20: D | S20: C | T20: B | U20: B | V20: A | W20: C | X20: D | Y20: D | Z20: B | AA20: A | AB20: B | AC20: C | AD20: B | AE20: C | AF20: A | AG20: B | AH20: D | AI20: B | AJ20: C | AK20: B | AL20: B | AM20: A | AN20: A | AO20: B | AP20: A | AQ20: B | AR20: A | AS20: B | AT20: B
A21: 833771 | B21: Perales, April | C21: 43958 | D21: AKPerales1@MY.SCCCD.EDU | E21: {=SUMPRODUCT(--(L21:AJ21=IF(K21="A",$L$2:$AJ$2,$L$3:$AJ$3)))} -> 9 | F21: {=SUMPRODUCT(--(AK21:AT21=IF(K21="A",$AK$2:$AT$2,$AK$3:$AT$3)))} -> 6 | G21: =E21*3+F21 -> 33 | H21: =G21*100/85 -> 38.823529 | I21: =(H21-$H$58)/$H$59 -> -1.0043629 | J21: A | K21: A | L21: A | M21: C | N21: A | O21: B | P21: B | Q21: D | R21: A | S21: B | T21: C | U21: A | V21: D | W21: C | X21: D | Y21: B | Z21: C | AA21: D | AB21: A | AC21: C | AD21: C | AE21: B | AF21: B | AG21: D | AH21: B | AI21: A | AJ21: D | AK21: B | AL21: A | AM21: B | AN21: A | AO21: A | AP21: A | AQ21: A | AR21: B | AS21: B | AT21: A
A22: 871988 | B22: Hernan, Jazmine | C22: 43957 | D22: JHHernan1@MY.SCCCD.EDU | E22: {=SUMPRODUCT(--(L22:AJ22=IF(K22="A",$L$2:$AJ$2,$L$3:$AJ$3)))} -> 11 | F22: {=SUMPRODUCT(--(AK22:AT22=IF(K22="A",$AK$2:$AT$2,$AK$3:$AT$3)))} -> 6 | G22: =E22*3+F22 -> 39 | H22: =G22*100/85 -> 45.882353 | I22: =(H22-$H$58)/$H$59 -> -0.63935689 | J22: A | K22: A | L22: A | M22: E | N22: B | O22: B | P22: C | Q22: B | R22: D | S22: A | T22: C | U22: A | V22: D | W22: C | X22: D | Y22: B | Z22: B | AA22: D | AB22: B | AC22: C | AD22: C | AE22: A | AF22: D | AG22: A | AH22: A | AI22: A | AJ22: D | AK22: A | AL22: B | AM22: A | AN22: B | AO22: A | AP22: A | AQ22: A | AR22: B | AS22: B | AT22: A
A23: 873290 | B23: Aquino, Hailey | C23: 43957 | D23: HJAquino1@MY.SCCCD.EDU | E23: {=SUMPRODUCT(--(L23:AJ23=IF(K23="A",$L$2:$AJ$2,$L$3:$AJ$3)))} -> 24 | F23: {=SUMPRODUCT(--(AK23:AT23=IF(K23="A",$AK$2:$AT$2,$AK$3:$AT$3)))} -> 10 | G23: =E23*3+F23 -> 82 | H23: =G23*100/85 -> 96.470588 | I23: =(H23-$H$58)/$H$59 -> 1.9765194 | J23: B | K23: B | L23: B | M23: A | N23: D | O23: B | P23: C | Q23: B | R23: D | S23: C | T23: C | U23: A | V23: A | W23: D | X23: C | Y23: B | Z23: B | AA23: C | AB23: B | AC23: A | AD23: C | AE23: C | AF23: B | AG23: A | AH23: D | AI23: D | AJ23: B | AK23: B | AL23: A | AM23: A | AN23: B | AO23: A | AP23: A | AQ23: B | AR23: A | AS23: B | AT23: A
... A56: 1070102 | B56: Becerril, Destiny | C56: 43958 | D56: DVBecerril1@MY.SCCCD.EDU | E56: {=SUMPRODUCT(--(L56:AJ56=IF(K56="A",$L$2:$AJ$2,$L$3:$AJ$3)))} -> 11 | F56: {=SUMPRODUCT(--(AK56:AT56=IF(K56="A",$AK$2:$AT$2,$AK$3:$AT$3)))} -> 7 | G56: =E56*3+F56 -> 40 | H56: =G56*100/85 -> 47.058824 | I56: =(H56-$H$58)/$H$59 -> -0.57852256 | J56: A | K56: A | L56: A | M56: B | N56: B | O56: B | P56: C | Q56: C | R56: D | S56: A | T56: C | U56: C | V56: D | W56: C | X56: D | Y56: A | Z56: B | AA56: B | AB56: A | AC56: C | AD56: C | AE56: C | AF56: D | AG56: D | AH56: C | AI56: A | AJ56: A | AK56: B | AL56: A | AM56: A | AN56: B | AO56: B | AP56: A | AQ56: B | AR56: B | AS56: A | AT56: A
G58: mean | H58: =AVERAGE(H6:H56) -> 58.246828
G59: std dev | H59: =_xlfn.STDEV.P(H6:H56) -> 19.338925
G60: max | H60: =MAX(H6:H56) -> 96.470588
G61: min | H61: =MIN(H6:H56) -> 22.352941
G62: median | H62: =MEDIAN(H6:H56) -> 57.647059
G63: count | H63: =COUNT(H6:H56) -> 51

Sheet Summary
F1: M/C Correct | G1: T/F Correct | H1: Raw Score | I1: Adjusted Score | J1: Z value
O2: Updated Keys
A3: 1 | B3: ='Raw Analysis'!A13 -> 694264 | C3: ='Raw Analysis'!B13 -> Andrade, Antonio | D3: ='Raw Analysis'!C13 -> 43957 | E3: ='Raw Analysis'!D13 -> AAndrade26@MY.SCCCD.EDU | F3: ='Raw Analysis'!E13 -> 21 | G3: ='Raw Analysis'!F13 -> 10 | H3: ='Raw Analysis'!G13 -> 73 | I3: ='Raw Analysis'!H13 -> 85.882353 | J3: ='Raw Analysis'!I13 -> 1.4290104 | N3: Q | O3: A | P3: B | R3: A | S3: B
A4: 2 | B4: ='Raw Analysis'!A23 -> 873290 | C4: ='Raw Analysis'!B23 -> Aquino, Hailey | D4: ='Raw Analysis'!C23 -> 43957 | E4: ='Raw Analysis'!D23 -> HJAquino1@MY.SCCCD.EDU | F4: ='Raw Analysis'!E23 -> 24 | G4: ='Raw Analysis'!F23 -> 10 | H4: ='Raw Analysis'!G23 -> 82 | I4: ='Raw Analysis'!H23 -> 96.470588 | J4: ='Raw Analysis'!I23 -> 1.9765194
A5: 3 | B5: ='Raw Analysis'!A40 -> 1016534 | C5: ='Raw Analysis'!B40 -> Arellano Cruz, Ashley | D5: ='Raw Analysis'!C40 -> 43958 | E5: ='Raw Analysis'!D40 -> AMArellanoCruz1@MY.SCCCD.EDU | F5: ='Raw Analysis'!E40 -> 6 | G5: ='Raw Analysis'!F40 -> 6 | H5: ='Raw Analysis'!G40 -> 24 | I5: ='Raw Analysis'!H40 -> 28.235294 | J5: ='Raw Analysis'!I40 -> -1.5518719 | N5: 1 | O5: A | P5: B | R5: A | S5: B
A6: 4 | B6: ='Raw Analysis'!A56 -> 1070102 | C6: ='Raw Analysis'!B56 -> Becerril, Destiny | D6: ='Raw Analysis'!C56 -> 43958 | E6: ='Raw Analysis'!D56 -> DVBecerril1@MY.SCCCD.EDU | F6: ='Raw Analysis'!E56 -> 11 | G6: ='Raw Analysis'!F56 -> 7 | H6: ='Raw Analysis'!G56 -> 40 | I6: ='Raw Analysis'!H56 -> 47.058824 | J6: ='Raw Analysis'!I56 -> -0.57852256 | N6: 2 | O6: D | P6: A | R6: D | S6: A
A7: 5 | B7: ='Raw Analysis'!A48 -> 1065569 | C7: ='Raw Analysis'!B48 -> Bryant, Tajanique | D7: ='Raw Analysis'!C48 -> 43958 | E7: ='Raw Analysis'!D48 -> TMBryant1@MY.SCCCD.EDU | F7: ='Raw Analysis'!E48 -> 14 | G7: ='Raw Analysis'!F48 -> 8 | H7: ='Raw Analysis'!G48 -> 50 | I7: ='Raw Analysis'!H48 -> 58.823529 | J7: ='Raw Analysis'!I48 -> 0.029820751 | N7: 3 | O7: C | P7: D | R7: C | S7: D
A8: 6 | B8: ='Raw Analysis'!A16 -> 759215 | C8: ='Raw Analysis'!B16 -> Castro, Socorro | D8: ='Raw Analysis'!C16 -> 43958 | E8: ='Raw Analysis'!D16 -> SCastro42@MY.SCCCD.EDU | F8: ='Raw Analysis'!E16 -> 22 | G8: ='Raw Analysis'!F16 -> 10 | H8: ='Raw Analysis'!G16 -> 76 | I8: ='Raw Analysis'!H16 -> 89.411765 | J8: ='Raw Analysis'!I16 -> 1.6115134 | N8: 4 | O8: B | P8: B | R8: B | S8: B | T8: Gifted
A9: 7 | B9: ='Raw Analysis'!A11 -> 576373 | C9: ='Raw Analysis'!B11 -> Ceballos, Ariel | D9: ='Raw Analysis'!C11 -> 43957 | E9: ='Raw Analysis'!D11 -> AMCeballos1@MY.SCCCD.EDU | F9: ='Raw Analysis'!E11 -> 15 | G9: ='Raw Analysis'!F11 -> 8 | H9: ='Raw Analysis'!G11 -> 53 | I9: ='Raw Analysis'!H11 -> 62.352941 | J9: ='Raw Analysis'!I11 -> 0.21232374 | N9: 5 | O9: B | P9: C | R9: B | S9: C
A10: 8 | B10: ='Raw Analysis'!A36 -> 994114 | C10: ='Raw Analysis'!B36 -> Corea, Kristie | D10: ='Raw Analysis'!C36 -> 43957 | E10: ='Raw Analysis'!D36 -> KNCorea1@MY.SCCCD.EDU | F10: ='Raw Analysis'!E36 -> 14 | G10: ='Raw Analysis'!F36 -> 7 | H10: ='Raw Analysis'!G36 -> 49 | I10: ='Raw Analysis'!H36 -> 57.647059 | J10: ='Raw Analysis'!I36 -> -0.031013581 | N10: 6 | O10: B | P10: B | R10: B | S10: B
A11: 9 | B11: ='Raw Analysis'!A41 -> 1024952 | C11: ='Raw Analysis'!B41 -> Cuevas Romero, Ana | D11: ='Raw Analysis'!C41 -> 43957 | E11: ='Raw Analysis'!D41 -> ADCuevasRomero1@MY.SCCCD.EDU | F11: ='Raw Analysis'!E41 -> 18 | G11: ='Raw Analysis'!F41 -> 10 | H11: ='Raw Analysis'!G41 -> 64 | I11: ='Raw Analysis'!H41 -> 75.294118 | J11: ='Raw Analysis'!I41 -> 0.88150139 | N11: 7 | O11: D | P11: D | R11: D | S11: D
A12: 10 | B12: ='Raw Analysis'!A24 -> 888543 | C12: ='Raw Analysis'!B24 -> Esparza, Beatrice | D12: ='Raw Analysis'!C24 -> 43957 | E12: ='Raw Analysis'!D24 -> BMEsparza1@MY.SCCCD.EDU | F12: ='Raw Analysis'!E24 -> 20 | G12: ='Raw Analysis'!F24 -> 10 | H12: ='Raw Analysis'!G24 -> 70 | I12: ='Raw Analysis'!H24 -> 82.352941 | J12: ='Raw Analysis'!I24 -> 1.2465074 | N12: 8 | O12: C | P12: C | R12: C | S12: C
A13: 11 | B13: ='Raw Analysis'!A14 -> 737921 | C13: ='Raw Analysis'!B14 -> Fang, Pa | D13: ='Raw Analysis'!C14 -> 43957 | E13: ='Raw Analysis'!D14 -> PHFang1@MY.SCCCD.EDU | F13: ='Raw Analysis'!E14 -> 6 | G13: ='Raw Analysis'!F14 -> 5 | H13: ='Raw Analysis'!G14 -> 23 | I13: ='Raw Analysis'!H14 -> 27.058824 | J13: ='Raw Analysis'!I14 -> -1.6127062 | N13: 9 | O13: C | P13: C | R13: B | S13: B
A14: 12 | B14: ='Raw Analysis'!A44 -> 1039936 | C14: ='Raw Analysis'!B44 -> Gamez, Sergio | D14: ='Raw Analysis'!C44 -> 43957 | E14: ='Raw Analysis'!D44 -> SRGamez1@MY.SCCCD.EDU | F14: ='Raw Analysis'!E44 -> 12 | G14: ='Raw Analysis'!F44 -> 9 | H14: ='Raw Analysis'!G44 -> 45 | I14: ='Raw Analysis'!H44 -> 52.941176 | J14: ='Raw Analysis'!I44 -> -0.27435091 | N14: 10 | O14: A | P14: A | R14: A | S14: A
A15: 13 | B15: ='Raw Analysis'!A18 -> 790131 | C15: ='Raw Analysis'!B18 -> Garcia, Andres | D15: ='Raw Analysis'!C18 -> 43957 | E15: ='Raw Analysis'!D18 -> AGarcia679@MY.SCCCD.EDU | F15: ='Raw Analysis'!E18 -> 16 | G15: ='Raw Analysis'!F18 -> 8 | H15: ='Raw Analysis'!G18 -> 56 | I15: ='Raw Analysis'!H18 -> 65.882353 | J15: ='Raw Analysis'!I18 -> 0.39482674 | N15: 11 | O15: D | P15: A | R15: D | S15: A
A16: 14 | B16: ='Raw Analysis'!A52 -> 778750 | C16: ='Raw Analysis'!B52 -> Garcia, Jovanna | D16: ='Raw Analysis'!C52 -> 43958 | E16: ='Raw Analysis'!D52 -> JAGarcia38@MY.SCCCD.EDU | F16: ='Raw Analysis'!E52 -> 22 | G16: ='Raw Analysis'!F52 -> 10 | H16: ='Raw Analysis'!G52 -> 76 | I16: ='Raw Analysis'!H52 -> 89.411765 | J16: ='Raw Analysis'!I52 -> 1.6115134 | N16: 12 | O16: B | P16: D | R16: B | S16: D
A17: 15 | B17: ='Raw Analysis'!A7 -> 490011 | C17: ='Raw Analysis'!B7 -> Garcia, Sabrina | D17: ='Raw Analysis'!C7 -> 43957 | E17: ='Raw Analysis'!D7 -> SRGarcia4@MY.SCCCD.EDU | F17: ='Raw Analysis'!E7 -> 10 | G17: ='Raw Analysis'!F7 -> 3 | H17: ='Raw Analysis'!G7 -> 33 | I17: ='Raw Analysis'!H7 -> 38.823529 | J17: ='Raw Analysis'!I7 -> -1.0043629 | N17: 13 | O17: C | P17: C | R17: C | S17: C
A18: 16 | B18: ='Raw Analysis'!A47 -> 1063699 | C18: ='Raw Analysis'!B47 -> Garcia-Hernandez, Allison | D18: ='Raw Analysis'!C47 -> 43958 | E18: ='Raw Analysis'!D47 -> AGGarciaHernandez2@MY.SCCCD.EDU | F18: ='Raw Analysis'!E47 -> 12 | G18: ='Raw Analysis'!F47 -> 7 | H18: ='Raw Analysis'!G47 -> 43 | I18: ='Raw Analysis'!H47 -> 50.588235 | J18: ='Raw Analysis'!I47 -> -0.39601957 | N18: 14 | O18: B | P18: B | R18: B | S18: B
A19: 17 | B19: ='Raw Analysis'!A50 -> 928878 | C19: ='Raw Analysis'!B50 -> Her, Kangbao | D19: ='Raw Analysis'!C50 -> 43958 | E19: ='Raw Analysis'!D50 -> KHer133@MY.SCCCD.EDU | F19: ='Raw Analysis'!E50 -> 15 | G19: ='Raw Analysis'!F50 -> 9 | H19: ='Raw Analysis'!G50 -> 54 | I19: ='Raw Analysis'!H50 -> 63.529412 | J19: ='Raw Analysis'!I50 -> 0.27315808 | N19: 15 | O19: B | P19: B | R19: B | S19: B
A20: 18 | B20: ='Raw Analysis'!A22 -> 871988 | C20: ='Raw Analysis'!B22 -> Hernan, Jazmine | D20: ='Raw Analysis'!C22 -> 43957 | E20: ='Raw Analysis'!D22 -> JHHernan1@MY.SCCCD.EDU | F20: ='Raw Analysis'!E22 -> 11 | G20: ='Raw Analysis'!F22 -> 6 | H20: ='Raw Analysis'!G22 -> 39 | I20: ='Raw Analysis'!H22 -> 45.882353 | J20: ='Raw Analysis'!I22 -> -0.63935689 | N20: 16 | O20: A | P20: C | R20: A | S20: C
A21: 19 | B21: ='Raw Analysis'!A35 -> 982244 | C21: ='Raw Analysis'!B35 -> Hernandez Salcedo, Belen | D21: ='Raw Analysis'!C35 -> 43958 | E21: ='Raw Analysis'!D35 -> BGHernandezSalcedo1@MY.SCCCD.EDU | F21: ='Raw Analysis'!E35 -> 8 | G21: ='Raw Analysis'!F35 -> 4 | H21: ='Raw Analysis'!G35 -> 28 | I21: ='Raw Analysis'!H35 -> 32.941176 | J21: ='Raw Analysis'!I35 -> -1.3085345 | N21: 17 | O21: C | P21: B | R21: C | S21: B
A22: 20 | B22: ='Raw Analysis'!A55 -> 1038679 | C22: ='Raw Analysis'!B55 -> Hernandez, Arriel | D22: ='Raw Analysis'!C55 -> 43958 | E22: ='Raw Analysis'!D55 -> AHernandez641@MY.SCCCD.EDU | F22: ='Raw Analysis'!E55 -> 8 | G22: ='Raw Analysis'!F55 -> 6 | H22: ='Raw Analysis'!G55 -> 30 | I22: ='Raw Analysis'!H55 -> 35.294118 | J22: ='Raw Analysis'!I55 -> -1.1868659 | N22: 18 | O22: A | P22: A | R22: D | S22: A
A23: 21 | B23: ='Raw Analysis'!A31 -> 958268 | C23: ='Raw Analysis'!B31 -> Jimenez Merino, Oscar | D23: ='Raw Analysis'!C31 -> 43958 | E23: ='Raw Analysis'!D31 -> ODJimenezMerino1@MY.SCCCD.EDU | F23: ='Raw Analysis'!E31 -> 17 | G23: ='Raw Analysis'!F31 -> 7 | H23: ='Raw Analysis'!G31 -> 58 | I23: ='Raw Analysis'!H31 -> 68.235294 | J23: ='Raw Analysis'!I31 -> 0.5164954 | N23: 19 | O23: C | P23: C | R23: C | S23: C
A24: 22 | B24: ='Raw Analysis'!A45 -> 1043694 | C24: ='Raw Analysis'!B45 -> Khan, Hamza | D24: ='Raw Analysis'!C45 -> 43958 | E24: ='Raw Analysis'!D45 -> HAKhan2@MY.SCCCD.EDU | F24: ='Raw Analysis'!E45 -> 21 | G24: ='Raw Analysis'!F45 -> 10 | H24: ='Raw Analysis'!G45 -> 73 | I24: ='Raw Analysis'!H45 -> 85.882353 | J24: ='Raw Analysis'!I45 -> 1.4290104 | N24: 20 | O24: C | P24: C | R24: C | S24: C
A25: 23 | B25: ='Raw Analysis'!A51 -> 1028207 | C25: ='Raw Analysis'!B51 -> Lopez, Jovina | D25: ='Raw Analysis'!C51 -> 43957 | E25: ='Raw Analysis'!D51 -> JALopez110@MY.SCCCD.EDU | F25: ='Raw Analysis'!E51 -> 6 | G25: ='Raw Analysis'!F51 -> 6 | H25: ='Raw Analysis'!G51 -> 24 | I25: ='Raw Analysis'!H51 -> 28.235294 | J25: ='Raw Analysis'!I51 -> -1.5518719 | N25: 21 | O25: D | P25: B | R25: A | S25: E
A26: 24 | B26: ='Raw Analysis'!A34 -> 977963 | C26: ='Raw Analysis'!B34 -> Maravilla Martinez, Rogelio | D26: ='Raw Analysis'!C34 -> 43958 | E26: ='Raw Analysis'!D34 -> RMaravillaMartinez1@MY.SCCCD.EDU | F26: ='Raw Analysis'!E34 -> 6 | G26: ='Raw Analysis'!F34 -> 7 | H26: ='Raw Analysis'!G34 -> 25 | I26: ='Raw Analysis'!H34 -> 29.411765 | J26: ='Raw Analysis'!I34 -> -1.4910375 | N26: 22 | O26: D | P26: C | R26: D | S26: C
A27: 25 | B27: ='Raw Analysis'!A6 -> 345856 | C27: ='Raw Analysis'!B6 -> Marquez, Rocelia | D27: ='Raw Analysis'!C6 -> 43957 | E27: ='Raw Analysis'!D6 -> RMarquez33@MY.SCCCD.EDU | F27: ='Raw Analysis'!E6 -> 9 | G27: ='Raw Analysis'!F6 -> 8 | H27: ='Raw Analysis'!G6 -> 35 | I27: ='Raw Analysis'!H6 -> 41.176471 | J27: ='Raw Analysis'!I6 -> -0.88269422 | N27: 23 | O27: C | P27: D | R27: C | S27: D
A28: 26 | B28: ='Raw Analysis'!A20 -> 808147 | C28: ='Raw Analysis'!B20 -> Martinez, Vanessa | D28: ='Raw Analysis'!C20 -> 43958 | E28: ='Raw Analysis'!D20 -> VEMartinez2@MY.SCCCD.EDU | F28: ='Raw Analysis'!E20 -> 8 | G28: ='Raw Analysis'!F20 -> 6 | H28: ='Raw Analysis'!G20 -> 30 | I28: ='Raw Analysis'!H20 -> 35.294118 | J28: ='Raw Analysis'!I20 -> -1.1868659 | N28: 24 | O28: B | P28: D | R28: B | S28: D
A29: 27 | B29: ='Raw Analysis'!A12 -> 684403 | C29: ='Raw Analysis'!B12 -> Morgan, Steven | D29: ='Raw Analysis'!C12 -> 43958 | E29: ='Raw Analysis'!D12 -> SVMorgan1@MY.SCCCD.EDU | F29: ='Raw Analysis'!E12 -> 17 | G29: ='Raw Analysis'!F12 -> 10 | H29: ='Raw Analysis'!G12 -> 61 | I29: ='Raw Analysis'!H12 -> 71.764706 | J29: ='Raw Analysis'!I12 -> 0.69899839 | N29: 25 | O29: B | P29: B | R29: E | S29: B
A30: 28 | B30: ='Raw Analysis'!A54 -> 986455 | C30: ='Raw Analysis'!B54 -> Moua, Haley | D30: ='Raw Analysis'!C54 -> 43957 | E30: ='Raw Analysis'!D54 -> HNMoua3@MY.SCCCD.EDU | F30: ='Raw Analysis'!E54 -> 11 | G30: ='Raw Analysis'!F54 -> 8 | H30: ='Raw Analysis'!G54 -> 41 | I30: ='Raw Analysis'!H54 -> 48.235294 | J30: ='Raw Analysis'!I54 -> -0.51768823 | N30: 26 | O30: B | P30: B | R30: B | S30: B
A31: 29 | B31: ='Raw Analysis'!A46 -> 1047765 | C31: ='Raw Analysis'!B46 -> Munoz Cisneros, Evelyn | D31: ='Raw Analysis'!C46 -> 43957 | E31: ='Raw Analysis'!D46 -> EMunozCisneros1@MY.SCCCD.EDU | F31: ='Raw Analysis'!E46 -> 5 | G31: ='Raw Analysis'!F46 -> 4 | H31: ='Raw Analysis'!G46 -> 19 | I31: ='Raw Analysis'!H46 -> 22.352941 | J31: ='Raw Analysis'!I46 -> -1.8560435 | L31: 75.3 | N31: 27 | O31: A | P31: A | R31: A | S31: A
A32: 30 | B32: ='Raw Analysis'!A39 -> 1014825 | C32: ='Raw Analysis'!B39 -> Musso, Isabella | D32: ='Raw Analysis'!C39 -> 43958 | E32: ='Raw Analysis'!D39 -> IRMusso1@MY.SCCCD.EDU | F32: ='Raw Analysis'!E39 -> 20 | G32: ='Raw Analysis'!F39 -> 9 | H32: ='Raw Analysis'!G39 -> 69 | I32: ='Raw Analysis'!H39 -> 81.176471 | J32: ='Raw Analysis'!I39 -> 1.185673 | N32: 28 | O32: A | P32: A | R32: A | S32: A
A33: 31 | B33: ='Raw Analysis'!A33 -> 977589 | C33: ='Raw Analysis'!B33 -> Negrete, Miguel | D33: ='Raw Analysis'!C33 -> 43958 | E33: ='Raw Analysis'!D33 -> MNegrete25@MY.SCCCD.EDU | F33: ='Raw Analysis'!E33 -> 17 | G33: ='Raw Analysis'!F33 -> 10 | H33: ='Raw Analysis'!G33 -> 61 | I33: ='Raw Analysis'!H33 -> 71.764706 | J33: ='Raw Analysis'!I33 -> 0.69899839 | N33: 29 | O33: B | P33: B | R33: B | S33: B
A34: 32 | B34: ='Raw Analysis'!A38 -> 1012960 | C34: ='Raw Analysis'!B38 -> Nounvilaythong, Samaria | D34: ='Raw Analysis'!C38 -> 43957 | E34: ='Raw Analysis'!D38 -> SVNounvilaythong1@MY.SCCCD.EDU | F34: ='Raw Analysis'!E38 -> 10 | G34: ='Raw Analysis'!F38 -> 9 | H34: ='Raw Analysis'!G38 -> 39 | I34: ='Raw Analysis'!H38 -> 45.882353 | J34: ='Raw Analysis'!I38 -> -0.63935689 | N34: 30 | O34: A | P34: A | R34: B | S34: B
A35: 33 | B35: ='Raw Analysis'!A43 -> 1039827 | C35: ='Raw Analysis'!B43 -> Olea, Joscelyne | D35: ='Raw Analysis'!C43 -> 43957 | E35: ='Raw Analysis'!D43 -> JDOlea1@MY.SCCCD.EDU | F35: ='Raw Analysis'!E43 -> 19 | G35: ='Raw Analysis'!F43 -> 10 | H35: ='Raw Analysis'!G43 -> 67 | I35: ='Raw Analysis'!H43 -> 78.823529 | J35: ='Raw Analysis'!I43 -> 1.0640044 | N35: 31 | O35: A | P35: A | R35: A | S35: A
A36: 34 | B36: ='Raw Analysis'!A19 -> 792916 | C36: ='Raw Analysis'!B19 -> Parada, Jennifer | D36: ='Raw Analysis'!C19 -> 43958 | E36: ='Raw Analysis'!D19 -> JParada1@MY.SCCCD.EDU | F36: ='Raw Analysis'!E19 -> 18 | G36: ='Raw Analysis'!F19 -> 10 | H36: ='Raw Analysis'!G19 -> 64 | I36: ='Raw Analysis'!H19 -> 75.294118 | J36: ='Raw Analysis'!I19 -> 0.88150139 | N36: 32 | O36: B | P36: B | R36: A | S36: A
A37: 35 | B37: ='Raw Analysis'!A42 -> 1035199 | C37: ='Raw Analysis'!B42 -> Pascale, Teah | D37: ='Raw Analysis'!C42 -> 43957 | E37: ='Raw Analysis'!D42 -> TMPascale1@MY.SCCCD.EDU | F37: ='Raw Analysis'!E42 -> 13 | G37: ='Raw Analysis'!F42 -> 4 | H37: ='Raw Analysis'!G42 -> 43 | I37: ='Raw Analysis'!H42 -> 50.588235 | J37: ='Raw Analysis'!I42 -> -0.39601957 | N37: 33 | O37: A | P37: A | R37: B | S37: B
A38: 36 | B38: ='Raw Analysis'!A26 -> 895473 | C38: ='Raw Analysis'!B26 -> Pedroza, Serena | D38: ='Raw Analysis'!C26 -> 43957 | E38: ='Raw Analysis'!D26 -> SRPedroza2@MY.SCCCD.EDU | F38: ='Raw Analysis'!E26 -> 16 | G38: ='Raw Analysis'!F26 -> 9 | H38: ='Raw Analysis'!G26 -> 57 | I38: ='Raw Analysis'!H26 -> 67.058824 | J38: ='Raw Analysis'!I26 -> 0.45566107 | N38: 34 | O38: B | P38: B | R38: B | S38: B
A39: 37 | B39: ='Raw Analysis'!A21 -> 833771 | C39: ='Raw Analysis'!B21 -> Perales, April | D39: ='Raw Analysis'!C21 -> 43958 | E39: ='Raw Analysis'!D21 -> AKPerales1@MY.SCCCD.EDU | F39: ='Raw Analysis'!E21 -> 9 | G39: ='Raw Analysis'!F21 -> 6 | H39: ='Raw Analysis'!G21 -> 33 | I39: ='Raw Analysis'!H21 -> 38.823529 | J39: ='Raw Analysis'!I21 -> -1.0043629 | N39: 35 | O39: A | P39: A | R39: A | S39: A
A40: 38 | B40: ='Raw Analysis'!A8 -> 523330 | C40: ='Raw Analysis'!B8 -> Pyle, Matthew | D40: ='Raw Analysis'!C8 -> 43957 | E40: ='Raw Analysis'!D8 -> MPyle1@MY.SCCCD.EDU | F40: ='Raw Analysis'!E8 -> 15 | G40: ='Raw Analysis'!F8 -> 8 | H40: ='Raw Analysis'!G8 -> 53 | I40: ='Raw Analysis'!H8 -> 62.352941 | J40: ='Raw Analysis'!I8 -> 0.21232374
...
